Workbook

Sheet Read me
B2: DNL — item 11: what the explicit period does to capital intensity
B4: What this is
B5: Four ways of deciding how much capital Denali has to put back into the business over the ten-year explicit period, each carried all the way through to a value per share. Every sheet is live: change an input on 'Inputs' and all four rebuild.
B6: The four sheets differ in exactly one block of rows — the capex derivation. Everything above and below it is identical, so the difference in the answer is attributable to that block and to nothing else.
B8: Why it matters
B9: Capex converging to 7.3% of revenue matters because D&A is also 7.3%. A business reinvesting exactly what it depreciates adds no net fixed capital. Denali's revenue compounds about 50% over the ten years, so its invested capital falls from 108% of revenue to 73%. That thinning, not a competitive moat, is what produces the high terminal return the framework then capitalises forever.
B11: The four positions
B12: 1 Ruled build
B13: Capex follows the declared path: 7.86% in Y1 converging to 7.3% by Y5 (D-38). 7.3% is also D&A, so from Y5 the fixed asset base stops growing in nominal terms.
B15: 2 Hold intensity
B16: Capex is whatever restores the opening ratio of fixed capital to revenue, every year. The asset base grows exactly as fast as revenue.
B18: 3 Volume + inflation
... B31: Inputs are the live DNL data files as at the 25 May 2026 valuation date, read through the translator. Invested capital of 3,681.1m is D-44: net PP&E plus intangibles plus non-cash working capital, goodwill excluded. Generated 26 August 2026.

Sheet Inputs
A1: DNL — Muddle Through, inputs
A2: Blue cells are inputs. Change one and every position sheet rebuilds.
A4: Scalar assumptions
A5: Base year revenue ($mm) | B5: 3400 | C5: FY2026 normalised revenue
A6: Stub period (years) | B6: 0.351 | C6: 25 May 2026 to 30 September 2026
A7: Base EBIT margin | B7: 0.141 | C7: Normalised, before scenario overlays
A8: D&A, % of revenue | B8: 0.073 | C8: Held flat across the horizon
A9: Capex in the stub, % of revenue | B9: 0.08 | C9: Declared separately from Y1
A10: Working capital intensity | B10: 0.1376 | C10: Applied to the change in the revenue run-rate (D-29)
A11: Tax rate, stub | B11: 0.225 | C11: Glides per year below
A12: WACC | B12: 0.088771579 | C12: Scalar, per the live build
A13: Terminal growth (g) | B13: 0.025 | C13: Declared basis pending D-45
A14: Invested capital at valuation date ($mm) | B14: 3681.1 | C14: D-44: net PP&E + intangibles + NCWC, goodwill excluded
A16: Growth chain (the split that decides positions 3 and 4)
A17: Chain nominal growth (B42) | B17: 0.061548876 | C17: What the explicit period grows at before the fade
A18: Industry volume growth (B25) | B18: 0.03275 | C18: Needs capacity
A19: Industry pricing growth (B29) | B19: 0.0285 | C19: Does not need capacity
A20: Asset inflation used | B20: 0.025 | C20: Set equal to terminal growth; change here to test it
A22: Equity bridge ($mm)
A23: Net debt at valuation date | B23: 1224.0329
A24: Other bridge adjustments, net | B24: 151.65
A25: Lease liabilities | B25: 194.3
A26: Shares outstanding (m) | B26: 1770
A28: Per-year inputs
A29: Year | C29: Y1 | D29: Y2 | E29: Y3 | F29: Y4 | G29: Y5 | H29: Y6 | I29: Y7 | J29: Y8 | K29: Y9 | L29: Y10
A30: Revenue growth (faded) | C30: 0.061548876 | D30: 0.061548876 | E30: 0.061548876 | F30: 0.061548876 | G30: 0.061548876 | H30: 0.054239101 | I30: 0.046929326 | J30: 0.039619551 | K30: 0.032309775 | L30: 0.025 | O30: Chain rate for five years, then a linear glide onto g in Y10 (D-36)
A31: Margin overlay vs base (pp) | C31: 0.00525 | D31: 0.0135 | E31: 0.011 | F31: 0.00725 | G31: 0.00575 | H31: 0.005 | I31: 0.005 | J31: 0.005 | K31: 0.005 | L31: 0.005 | O31: Transformation plus the re-phased gas roll-off (D-40)
A32: Tax rate | C32: 0.225 | D32: 0.2375 | E32: 0.25 | F32: 0.2625 | G32: 0.275 | H32: 0.275 | I32: 0.275 | J32: 0.275 | K32: 0.275 | L32: 0.275
A33: Capex, % of revenue — position 1 only | C33: 0.0786 | D33: 0.0772 | E33: 0.0758 | F33: 0.0744 | G33: 0.073 | H33: 0.073 | I33: 0.073 | J33: 0.073 | K33: 0.073 | L33: 0.073 | O33: Converges to 7.3% by Y5 (D-38). Positions 2-4 derive their own.

Sheet 1 Ruled build
A1: 1 Ruled build — Muddle Through
A2: Capex follows the declared path: 7.86% in Y1 converging to 7.3% by Y5 (D-38). 7.3% is also D&A, so from Y5 the fixed asset base stops growing in nominal terms.
A4: Period | C4: Stub | D4: Y1 | E4: Y2 | F4: Y3 | G4: Y4 | H4: Y5 | I4: Y6 | J4: Y7 | K4: Y8 | L4: Y9 | M4: Y10
A5: Revenue ($mm) | C5: =Inputs!$B$5*Inputs!$B$6 -> 1193.4 | D5: =Inputs!$B$5*(1+Inputs!C$30) -> 3609.2662 | E5: =D5*(1+Inputs!D$30) -> 3831.4125 | F5: =E5*(1+Inputs!E$30) -> 4067.2316 | G5: =F5*(1+Inputs!F$30) -> 4317.5651 | H5: =G5*(1+Inputs!G$30) -> 4583.3064 | I5: =H5*(1+Inputs!H$30) -> 4831.9008 | J5: =I5*(1+Inputs!I$30) -> 5058.6587 | K5: =J5*(1+Inputs!J$30) -> 5259.0805 | L5: =K5*(1+Inputs!K$30) -> 5429.0002 | M5: =L5*(1+Inputs!L$30) -> 5564.7252
A6: Revenue run-rate at period end ($mm) | C6: =Inputs!$B$5*(1+Inputs!$C$30)^Inputs!$B$6 -> 3472.0331 | D6: =D5 -> 3609.2662 | E6: =E5 -> 3831.4125 | F6: =F5 -> 4067.2316 | G6: =G5 -> 4317.5651 | H6: =H5 -> 4583.3064 | I6: =I5 -> 4831.9008 | J6: =J5 -> 5058.6587 | K6: =K5 -> 5259.0805 | ... M6: =M5 -> 5564.7252
A7: EBIT margin | C7: =Inputs!$B$7 -> 0.141 | D7: =Inputs!$B$7+Inputs!C$31 -> 0.14625 | E7: =Inputs!$B$7+Inputs!D$31 -> 0.1545 | F7: =Inputs!$B$7+Inputs!E$31 -> 0.152 | G7: =Inputs!$B$7+Inputs!F$31 -> 0.14825 | H7: =Inputs!$B$7+Inputs!G$31 -> 0.14675 | I7: =Inputs!$B$7+Inputs!H$31 -> 0.146 | J7: =Inputs!$B$7+Inputs!I$31 -> 0.146 | K7: =Inputs!$B$7+Inputs!J$31 -> 0.146 | ... M7: =Inputs!$B$7+Inputs!L$31 -> 0.146
A8: EBIT ($mm) | C8: =C5*C7 -> 168.2694 | D8: =D5*D7 -> 527.85518 | E8: =E5*E7 -> 591.95322 | F8: =F5*F7 -> 618.2192 | G8: =G5*G7 -> 640.07903 | H8: =H5*H7 -> 672.60021 | I8: =I5*I7 -> 705.45752 | J8: =J5*J7 -> 738.56417 | ... M8: =M5*M7 -> 812.44987
A9: Tax rate | C9: =Inputs!$B$11 -> 0.225 | D9: =Inputs!C$32 -> 0.225 | E9: =Inputs!D$32 -> 0.2375 | F9: =Inputs!E$32 -> 0.25 | G9: =Inputs!F$32 -> 0.2625 | H9: =Inputs!G$32 -> 0.275 | I9: =Inputs!H$32 -> 0.275 | J9: =Inputs!I$32 -> 0.275 | K9: =Inputs!J$32 -> 0.275 | ... M9: =Inputs!L$32 -> 0.275
A10: NOPAT ($mm) | C10: =C8*(1-C9) -> 130.40878 | D10: =D8*(1-D9) -> 409.08776 | E10: =E8*(1-E9) -> 451.36433 | F10: =F8*(1-F9) -> 463.6644 | G10: =G8*(1-G9) -> 472.05828 | H10: =H8*(1-H9) -> 487.63516 | I10: =I8*(1-I9) -> 511.4567 | J10: =J8*(1-J9) -> 535.45902 | ... M10: =M8*(1-M9) -> 589.02616
A11: D&A ($mm) | C11: =C5*Inputs!$B$8 -> 87.1182 | D11: =D5*Inputs!$B$8 -> 263.47643 | E11: =E5*Inputs!$B$8 -> 279.69311 | F11: =F5*Inputs!$B$8 -> 296.90791 | G11: =G5*Inputs!$B$8 -> 315.18225 | H11: =H5*Inputs!$B$8 -> 334.58137 | I11: =I5*Inputs!$B$8 -> 352.72876 | J11: =J5*Inputs!$B$8 -> 369.28208 | ... M11: =M5*Inputs!$B$8 -> 406.22494
A13: The capex derivation — the only block that differs
A14: Capex, % of revenue (declared path) | C14: =Inputs!$B$9 -> 0.08 | D14: =Inputs!C$33 -> 0.0786 | E14: =Inputs!D$33 -> 0.0772 | F14: =Inputs!E$33 -> 0.0758 | G14: =Inputs!F$33 -> 0.0744 | H14: =Inputs!G$33 -> 0.073 | I14: =Inputs!H$33 -> 0.073 | J14: =Inputs!I$33 -> 0.073 | K14: =Inputs!J$33 -> 0.073 | ... M14: =Inputs!L$33 -> 0.073
A15: Capex less D&A, % of revenue | C15: =C14-Inputs!$B$8 -> 0.007 | D15: =D14-Inputs!$B$8 -> 0.0056 | E15: =E14-Inputs!$B$8 -> 0.0042 | F15: =F14-Inputs!$B$8 -> 0.0028 | G15: =G14-Inputs!$B$8 -> 0.0014 | H15: =H14-Inputs!$B$8 -> 0 | I15: =I14-Inputs!$B$8 -> 0 | J15: =J14-Inputs!$B$8 -> 0 | ... M15: =M14-Inputs!$B$8 -> 0 | O15: Zero from Y5: no net fixed capital is added.
A16: Capex ($mm) | C16: =C5*C14 -> 95.472 | D16: =D5*D14 -> 283.68832 | E16: =E5*E14 -> 295.78504 | F16: =F5*F14 -> 308.29615 | G16: =G5*G14 -> 321.22685 | H16: =H5*H14 -> 334.58137 | I16: =I5*I14 -> 352.72876 | J16: =J5*J14 -> 369.28208 | ... M16: =M5*M14 -> 406.22494
A18: Increase in working capital ($mm) | C18: =Inputs!$B$10*(C6-Inputs!$B$5) -> 9.9117529 | D18: =Inputs!$B$10*(D5-C6) -> 18.883273 | E18: =Inputs!$B$10*(E5-D5) -> 30.567328 | F18: =Inputs!$B$10*(F5-E5) -> 32.448712 | G18: =Inputs!$B$10*(G5-F5) -> 34.445894 | H18: =Inputs!$B$10*(H5-G5) -> 36.566 | I18: =Inputs!$B$10*(I5-H5) -> 34.206592 | J18: =Inputs!$B$10*(J5-I5) -> 31.20188 | K18: =Inputs!$B$10*(K5-J5) -> 27.578037 | L18: =Inputs!$B$10*(L5-K5) -> 23.380952 | M18: =Inputs!$B$10*(M5-L5) -> 18.675761
A19: Free cash flow to the firm ($mm) | C19: =C10+C11-C16-C18 -> 112.14323 | D19: =D10+D11-D16-D18 -> 369.9926 | E19: =E10+E11-E16-E18 -> 404.70507 | F19: =F10+F11-F16-F18 -> 419.82744 | G19: =G10+G11-G16-G18 -> 431.5678 | H19: =H10+H11-H16-H18 -> 451.06916 | I19: =I10+I11-I16-I18 -> 477.25011 | J19: =J10+J11-J16-J18 -> 504.25714 | ... M19: =M10+M11-M16-M18 -> 570.3504
A20: Discounting time (mid-year, years) | C20: =Inputs!$B$6/2 -> 0.1755 | D20: =Inputs!$B$6+1-0.5 -> 0.851 | E20: =Inputs!$B$6+2-0.5 -> 1.851 | F20: =Inputs!$B$6+3-0.5 -> 2.851 | G20: =Inputs!$B$6+4-0.5 -> 3.851 | H20: =Inputs!$B$6+5-0.5 -> 4.851 | I20: =Inputs!$B$6+6-0.5 -> 5.851 | J20: =Inputs!$B$6+7-0.5 -> 6.851 | K20: =Inputs!$B$6+8-0.5 -> 7.851 | L20: =Inputs!$B$6+9-0.5 -> 8.851 | M20: =Inputs!$B$6+10-0.5 -> 9.851
A21: Present value of FCFF ($mm) | C21: =C19/(1+Inputs!$B$12)^C20 -> 110.48178 | D21: =D19/(1+Inputs!$B$12)^D20 -> 344.15956 | E21: =E19/(1+Inputs!$B$12)^E20 -> 345.75517 | F21: =F19/(1+Inputs!$B$12)^F20 -> 329.4307 | G21: =G19/(1+Inputs!$B$12)^G20 -> 311.03231 | H21: =H19/(1+Inputs!$B$12)^H20 -> 298.58146 | I21: =I19/(1+Inputs!$B$12)^I20 -> 290.15427 | J21: =J19/(1+Inputs!$B$12)^J20 -> 281.57767 | ... M21: =M19/(1+Inputs!$B$12)^M20 -> 246.7616
A23: Invested capital, rolled forward
A24: Invested capital, closing ($mm) | B24: =Inputs!$B$14 -> 3681.1 | C24: =$B$24+C16-C11+C18 -> 3699.3656 | D24: =C24+D16-D11+D18 -> 3738.4607 | E24: =D24+E16-E11+E18 -> 3785.12 | F24: =E24+F16-F11+F18 -> 3828.9569 | G24: =F24+G16-G11+G18 -> 3869.4474 | H24: =G24+H16-H11+H18 -> 3906.0134 | I24: =H24+I16-I11+I18 -> 3940.22 | J24: =I24+J16-J11+J18 -> 3971.4219 | K24: =J24+K16-K11+K18 -> 3998.9999 | ... M24: =L24+M16-M11+M18 -> 4041.0566
A25: Invested capital ÷ revenue | B25: =$B$24/Inputs!$B$5 -> 1.0826765 | D25: =D24/D5 -> 1.0357952 | E25: =E24/E5 -> 0.98791765 | F25: =F24/F5 -> 0.94141601 | G25: =G24/G5 -> 0.89621055 | H25: =H24/H5 -> 0.85222612 | I25: =I24/I5 -> 0.81545962 | J25: =J24/J5 -> 0.7850741 | K25: =K24/K5 -> 0.76039908 | ... M25: =M24/M5 -> 0.7261916 | O25: Opening against Y10 is the whole of item 11.
A27: The terminal
A28: Terminal revenue ($mm) | B28: =M5*(1+Inputs!$B$13) -> 5703.8433
A29: Fixed capital at the end of Y10 ($mm) | B29: =M24-Inputs!$B$10*M5 -> 3275.3505
A30: Terminal capex, % of revenue | B30: =Inputs!$B$8+Inputs!$B$13*$B$29/M5 -> 0.08771479 | C30: The rate that grows the fixed base at g forever (D&A plus g times the base).
A31: Terminal FCFF ($mm) | B31: =$B$28*(M7*(1-M9)+Inputs!$B$8-$B$30-Inputs!$B$13*Inputs!$B$10) -> 500.19974
A32: Terminal value ($mm) | B32: =$B$31/(Inputs!$B$12-Inputs!$B$13) -> 7843.6153
A33: Present value of the terminal ($mm) | B33: =$B$32/(1+Inputs!$B$12)^(Inputs!$B$6+10) -> 3252.2485
A34: Terminal NOPAT ($mm) | B34: =$B$28*M7*(1-M9) -> 603.75181
A35: Terminal return on invested capital | B35: =$B$34/M24 -> 0.14940444
A36: Terminal ROIC ÷ WACC | B36: =$B$35/Inputs!$B$12 -> 1.6830211 | C36: Above 1.0x is an excess return the build has to defend.
A38: Value
A39: Present value of the explicit period ($mm) | B39: =SUM(C21:M21) -> 3088.9763
A40: Enterprise value ($mm) | B40: =$B$39+$B$33 -> 6341.2247
A41: Terminal share of enterprise value | B41: =$B$33/$B$40 -> 0.51287387 | C41: Above 70% triggers the §11.4.2 sensitivity obligation.
A42: Less net debt ($mm) | B42: =-Inputs!$B$23 -> -1224.0329
A43: Less other bridge adjustments ($mm) | B43: =-Inputs!$B$24 -> -151.65
A44: Less lease liabilities ($mm) | B44: =-Inputs!$B$25 -> -194.3
A45: Equity value ($mm) | B45: =$B$40+SUM($B$42:$B$44) -> 4771.2419
A46: Value per share ($) | B46: =$B$45/Inputs!$B$26 -> 2.6956169

Sheet 2 Hold intensity
A1: 2 Hold intensity — Muddle Through
A2: Capex is whatever restores the opening ratio of fixed capital to revenue, every year. The asset base grows exactly as fast as revenue.
A4: Period | C4: Stub | D4: Y1 | E4: Y2 | F4: Y3 | G4: Y4 | H4: Y5 | I4: Y6 | J4: Y7 | K4: Y8 | L4: Y9 | M4: Y10
A5: Revenue ($mm) | C5: =Inputs!$B$5*Inputs!$B$6 -> 1193.4 | D5: =Inputs!$B$5*(1+Inputs!C$30) -> 3609.2662 | E5: =D5*(1+Inputs!D$30) -> 3831.4125 | F5: =E5*(1+Inputs!E$30) -> 4067.2316 | G5: =F5*(1+Inputs!F$30) -> 4317.5651 | H5: =G5*(1+Inputs!G$30) -> 4583.3064 | I5: =H5*(1+Inputs!H$30) -> 4831.9008 | J5: =I5*(1+Inputs!I$30) -> 5058.6587 | K5: =J5*(1+Inputs!J$30) -> 5259.0805 | L5: =K5*(1+Inputs!K$30) -> 5429.0002 | M5: =L5*(1+Inputs!L$30) -> 5564.7252
A6: Revenue run-rate at period end ($mm) | C6: =Inputs!$B$5*(1+Inputs!$C$30)^Inputs!$B$6 -> 3472.0331 | D6: =D5 -> 3609.2662 | E6: =E5 -> 3831.4125 | F6: =F5 -> 4067.2316 | G6: =G5 -> 4317.5651 | H6: =H5 -> 4583.3064 | I6: =I5 -> 4831.9008 | J6: =J5 -> 5058.6587 | K6: =K5 -> 5259.0805 | ... M6: =M5 -> 5564.7252
A7: EBIT margin | C7: =Inputs!$B$7 -> 0.141 | D7: =Inputs!$B$7+Inputs!C$31 -> 0.14625 | E7: =Inputs!$B$7+Inputs!D$31 -> 0.1545 | F7: =Inputs!$B$7+Inputs!E$31 -> 0.152 | G7: =Inputs!$B$7+Inputs!F$31 -> 0.14825 | H7: =Inputs!$B$7+Inputs!G$31 -> 0.14675 | I7: =Inputs!$B$7+Inputs!H$31 -> 0.146 | J7: =Inputs!$B$7+Inputs!I$31 -> 0.146 | K7: =Inputs!$B$7+Inputs!J$31 -> 0.146 | ... M7: =Inputs!$B$7+Inputs!L$31 -> 0.146
A8: EBIT ($mm) | C8: =C5*C7 -> 168.2694 | D8: =D5*D7 -> 527.85518 | E8: =E5*E7 -> 591.95322 | F8: =F5*F7 -> 618.2192 | G8: =G5*G7 -> 640.07903 | H8: =H5*H7 -> 672.60021 | I8: =I5*I7 -> 705.45752 | J8: =J5*J7 -> 738.56417 | ... M8: =M5*M7 -> 812.44987
A9: Tax rate | C9: =Inputs!$B$11 -> 0.225 | D9: =Inputs!C$32 -> 0.225 | E9: =Inputs!D$32 -> 0.2375 | F9: =Inputs!E$32 -> 0.25 | G9: =Inputs!F$32 -> 0.2625 | H9: =Inputs!G$32 -> 0.275 | I9: =Inputs!H$32 -> 0.275 | J9: =Inputs!I$32 -> 0.275 | K9: =Inputs!J$32 -> 0.275 | ... M9: =Inputs!L$32 -> 0.275
A10: NOPAT ($mm) | C10: =C8*(1-C9) -> 130.40878 | D10: =D8*(1-D9) -> 409.08776 | E10: =E8*(1-E9) -> 451.36433 | F10: =F8*(1-F9) -> 463.6644 | G10: =G8*(1-G9) -> 472.05828 | H10: =H8*(1-H9) -> 487.63516 | I10: =I8*(1-I9) -> 511.4567 | J10: =J8*(1-J9) -> 535.45902 | ... M10: =M8*(1-M9) -> 589.02616
A11: D&A ($mm) | C11: =C5*Inputs!$B$8 -> 87.1182 | D11: =D5*Inputs!$B$8 -> 263.47643 | E11: =E5*Inputs!$B$8 -> 279.69311 | F11: =F5*Inputs!$B$8 -> 296.90791 | G11: =G5*Inputs!$B$8 -> 315.18225 | H11: =H5*Inputs!$B$8 -> 334.58137 | I11: =I5*Inputs!$B$8 -> 352.72876 | J11: =J5*Inputs!$B$8 -> 369.28208 | ... M11: =M5*Inputs!$B$8 -> 406.22494
A13: The capex derivation — the only block that differs
A14: Fixed capital at valuation date ($mm) | B14: =Inputs!$B$14-Inputs!$B$10*Inputs!$B$5 -> 3213.26 | C14: Invested capital less the working-capital stock
A15: Opening fixed capital ÷ revenue | B15: =$B$14/Inputs!$B$5 -> 0.94507647 | C15: Held constant in every year below
A16: Fixed capital growth (= revenue growth) | D16: =Inputs!C$30 -> 0.061548876 | E16: =Inputs!D$30 -> 0.061548876 | F16: =Inputs!E$30 -> 0.061548876 | G16: =Inputs!F$30 -> 0.061548876 | H16: =Inputs!G$30 -> 0.061548876 | I16: =Inputs!H$30 -> 0.054239101 | J16: =Inputs!I$30 -> 0.046929326 | K16: =Inputs!J$30 -> 0.039619551 | ... M16: =Inputs!L$30 -> 0.025
A17: Fixed capital, closing ($mm) | C17: =$B$14+C5*(Inputs!$B$9-Inputs!$B$8) -> 3221.6138 | D17: =$B$15*D5 -> 3411.0325 | E17: =$B$15*E5 -> 3620.9778 | F17: =$B$15*F5 -> 3843.8449 | G17: =$B$15*G5 -> 4080.4292 | H17: =$B$15*H5 -> 4331.575 | I17: =$B$15*I5 -> 4566.5158 | J17: =$B$15*J5 -> 4780.8193 | K17: =$B$15*K5 -> 4970.2332 | ... M17: =$B$15*M5 -> 5259.0908
A18: Capex ($mm) | C18: =C5*Inputs!$B$9 -> 95.472 | D18: =D17-C17+D5*Inputs!$B$8 -> 452.89517 | E18: =E17-D17+E5*Inputs!$B$8 -> 489.63833 | F18: =F17-E17+F5*Inputs!$B$8 -> 519.77502 | G18: =G17-F17+G5*Inputs!$B$8 -> 551.76659 | H18: =H17-G17+H5*Inputs!$B$8 -> 585.7272 | I18: =I17-H17+I5*Inputs!$B$8 -> 587.6695 | J18: =J17-I17+J5*Inputs!$B$8 -> 583.58559 | K18: =K17-J17+K5*Inputs!$B$8 -> 573.32678 | ... M18: =M17-L17+M5*Inputs!$B$8 -> 534.49544 | O18: Growth in the asset base, plus replacement of what depreciated.
A19: Capex, % of revenue (implied) | C19: =C18/C5 -> 0.08 | D19: =D18/D5 -> 0.12548123 | E19: =E18/E5 -> 0.12779578 | F19: =F18/F5 -> 0.12779578 | G19: =G18/G5 -> 0.12779578 | H19: =H18/H5 -> 0.12779578 | I19: =I18/I5 -> 0.12162284 | J19: =J18/J5 -> 0.1153637 | ... M19: =M18/M5 -> 0.096050646
A21: Increase in working capital ($mm) | C21: =Inputs!$B$10*(C6-Inputs!$B$5) -> 9.9117529 | D21: =Inputs!$B$10*(D5-C6) -> 18.883273 | E21: =Inputs!$B$10*(E5-D5) -> 30.567328 | F21: =Inputs!$B$10*(F5-E5) -> 32.448712 | G21: =Inputs!$B$10*(G5-F5) -> 34.445894 | H21: =Inputs!$B$10*(H5-G5) -> 36.566 | I21: =Inputs!$B$10*(I5-H5) -> 34.206592 | J21: =Inputs!$B$10*(J5-I5) -> 31.20188 | K21: =Inputs!$B$10*(K5-J5) -> 27.578037 | L21: =Inputs!$B$10*(L5-K5) -> 23.380952 | M21: =Inputs!$B$10*(M5-L5) -> 18.675761
A22: Free cash flow to the firm ($mm) | C22: =C10+C11-C18-C21 -> 112.14323 | D22: =D10+D11-D18-D21 -> 200.78575 | E22: =E10+E11-E18-E21 -> 210.85179 | F22: =F10+F11-F18-F21 -> 208.34858 | G22: =G10+G11-G18-G21 -> 201.02806 | H22: =H10+H11-H18-H21 -> 199.92332 | I22: =I10+I11-I18-I21 -> 242.30937 | J22: =J10+J11-J18-J21 -> 289.95363 | ... M22: =M10+M11-M18-M21 -> 442.07989
A23: Discounting time (mid-year, years) | C23: =Inputs!$B$6/2 -> 0.1755 | D23: =Inputs!$B$6+1-0.5 -> 0.851 | E23: =Inputs!$B$6+2-0.5 -> 1.851 | F23: =Inputs!$B$6+3-0.5 -> 2.851 | G23: =Inputs!$B$6+4-0.5 -> 3.851 | H23: =Inputs!$B$6+5-0.5 -> 4.851 | I23: =Inputs!$B$6+6-0.5 -> 5.851 | J23: =Inputs!$B$6+7-0.5 -> 6.851 | K23: =Inputs!$B$6+8-0.5 -> 7.851 | L23: =Inputs!$B$6+9-0.5 -> 8.851 | M23: =Inputs!$B$6+10-0.5 -> 9.851
A24: Present value of FCFF ($mm) | C24: =C22/(1+Inputs!$B$12)^C23 -> 110.48178 | D24: =D22/(1+Inputs!$B$12)^D23 -> 186.7668 | E24: =E22/(1+Inputs!$B$12)^E23 -> 180.13882 | F24: =F22/(1+Inputs!$B$12)^F23 -> 163.48721 | G24: =G22/(1+Inputs!$B$12)^G23 -> 144.88157 | H24: =H22/(1+Inputs!$B$12)^H23 -> 132.33757 | I24: =I22/(1+Inputs!$B$12)^I23 -> 147.31709 | J24: =J22/(1+Inputs!$B$12)^J23 -> 161.91038 | ... M24: =M22/(1+Inputs!$B$12)^M23 -> 191.26547
A26: Invested capital, rolled forward
A27: Invested capital, closing ($mm) | B27: =Inputs!$B$14 -> 3681.1 | C27: =$B$27+C18-C11+C21 -> 3699.3656 | D27: =C27+D18-D11+D21 -> 3907.6676 | E27: =D27+E18-E11+E21 -> 4148.1801 | F27: =E27+F18-F11+F21 -> 4403.4959 | G27: =F27+G18-G11+G21 -> 4674.5262 | H27: =G27+H18-H11+H21 -> 4962.238 | I27: =H27+I18-I11+I21 -> 5231.3853 | J27: =I27+J18-J11+J21 -> 5476.8907 | K27: =J27+K18-K11+K21 -> 5693.8827 | ... M27: =L27+M18-M11+M21 -> 6024.797
A28: Invested capital ÷ revenue | B28: =$B$27/Inputs!$B$5 -> 1.0826765 | D28: =D27/D5 -> 1.0826765 | E28: =E27/E5 -> 1.0826765 | F28: =F27/F5 -> 1.0826765 | G28: =G27/G5 -> 1.0826765 | H28: =H27/H5 -> 1.0826765 | I28: =I27/I5 -> 1.0826765 | J28: =J27/J5 -> 1.0826765 | K28: =K27/K5 -> 1.0826765 | ... M28: =M27/M5 -> 1.0826765 | O28: Opening against Y10 is the whole of item 11.
A30: The terminal
A31: Terminal revenue ($mm) | B31: =M5*(1+Inputs!$B$13) -> 5703.8433
A32: Fixed capital at the end of Y10 ($mm) | B32: =M27-Inputs!$B$10*M5 -> 5259.0908
A33: Terminal capex, % of revenue | B33: =Inputs!$B$8+Inputs!$B$13*$B$32/M5 -> 0.096626912 | C33: The rate that grows the fixed base at g forever (D&A plus g times the base).
A34: Terminal FCFF ($mm) | B34: =$B$31*(M7*(1-M9)+Inputs!$B$8-$B$33-Inputs!$B$13*Inputs!$B$10) -> 449.36639
A35: Terminal value ($mm) | B35: =$B$34/(Inputs!$B$12-Inputs!$B$13) -> 7046.4993
A36: Present value of the terminal ($mm) | B36: =$B$35/(1+Inputs!$B$12)^(Inputs!$B$6+10) -> 2921.7352
A37: Terminal NOPAT ($mm) | B37: =$B$31*M7*(1-M9) -> 603.75181
A38: Terminal return on invested capital | B38: =$B$37/M27 -> 0.10021115
A39: Terminal ROIC ÷ WACC | B39: =$B$38/Inputs!$B$12 -> 1.1288652 | C39: Above 1.0x is an excess return the build has to defend.
A41: Value
A42: Present value of the explicit period ($mm) | B42: =SUM(C24:M24) -> 1776.8378
A43: Enterprise value ($mm) | B43: =$B$42+$B$36 -> 4698.5729
A44: Terminal share of enterprise value | B44: =$B$36/$B$43 -> 0.62183459 | C44: Above 70% triggers the §11.4.2 sensitivity obligation.
A45: Less net debt ($mm) | B45: =-Inputs!$B$23 -> -1224.0329
A46: Less other bridge adjustments ($mm) | B46: =-Inputs!$B$24 -> -151.65
...

Sheet 3 Volume + inflation
A1: 3 Volume + inflation — Muddle Through
A2: Capital grows at the volume half of each year's revenue growth, inflated at asset inflation. Pricing growth needs no new capacity; volume and replacement cost do.
A4: Period | C4: Stub | D4: Y1 | E4: Y2 | F4: Y3 | G4: Y4 | H4: Y5 | I4: Y6 | J4: Y7 | K4: Y8 | L4: Y9 | M4: Y10
A5: Revenue ($mm) | C5: =Inputs!$B$5*Inputs!$B$6 -> 1193.4 | D5: =Inputs!$B$5*(1+Inputs!C$30) -> 3609.2662 | E5: =D5*(1+Inputs!D$30) -> 3831.4125 | F5: =E5*(1+Inputs!E$30) -> 4067.2316 | G5: =F5*(1+Inputs!F$30) -> 4317.5651 | H5: =G5*(1+Inputs!G$30) -> 4583.3064 | I5: =H5*(1+Inputs!H$30) -> 4831.9008 | J5: =I5*(1+Inputs!I$30) -> 5058.6587 | K5: =J5*(1+Inputs!J$30) -> 5259.0805 | L5: =K5*(1+Inputs!K$30) -> 5429.0002 | M5: =L5*(1+Inputs!L$30) -> 5564.7252
A6: Revenue run-rate at period end ($mm) | C6: =Inputs!$B$5*(1+Inputs!$C$30)^Inputs!$B$6 -> 3472.0331 | D6: =D5 -> 3609.2662 | E6: =E5 -> 3831.4125 | F6: =F5 -> 4067.2316 | G6: =G5 -> 4317.5651 | H6: =H5 -> 4583.3064 | I6: =I5 -> 4831.9008 | J6: =J5 -> 5058.6587 | K6: =K5 -> 5259.0805 | ... M6: =M5 -> 5564.7252
A7: EBIT margin | C7: =Inputs!$B$7 -> 0.141 | D7: =Inputs!$B$7+Inputs!C$31 -> 0.14625 | E7: =Inputs!$B$7+Inputs!D$31 -> 0.1545 | F7: =Inputs!$B$7+Inputs!E$31 -> 0.152 | G7: =Inputs!$B$7+Inputs!F$31 -> 0.14825 | H7: =Inputs!$B$7+Inputs!G$31 -> 0.14675 | I7: =Inputs!$B$7+Inputs!H$31 -> 0.146 | J7: =Inputs!$B$7+Inputs!I$31 -> 0.146 | K7: =Inputs!$B$7+Inputs!J$31 -> 0.146 | ... M7: =Inputs!$B$7+Inputs!L$31 -> 0.146
A8: EBIT ($mm) | C8: =C5*C7 -> 168.2694 | D8: =D5*D7 -> 527.85518 | E8: =E5*E7 -> 591.95322 | F8: =F5*F7 -> 618.2192 | G8: =G5*G7 -> 640.07903 | H8: =H5*H7 -> 672.60021 | I8: =I5*I7 -> 705.45752 | J8: =J5*J7 -> 738.56417 | ... M8: =M5*M7 -> 812.44987
A9: Tax rate | C9: =Inputs!$B$11 -> 0.225 | D9: =Inputs!C$32 -> 0.225 | E9: =Inputs!D$32 -> 0.2375 | F9: =Inputs!E$32 -> 0.25 | G9: =Inputs!F$32 -> 0.2625 | H9: =Inputs!G$32 -> 0.275 | I9: =Inputs!H$32 -> 0.275 | J9: =Inputs!I$32 -> 0.275 | K9: =Inputs!J$32 -> 0.275 | ... M9: =Inputs!L$32 -> 0.275
A10: NOPAT ($mm) | C10: =C8*(1-C9) -> 130.40878 | D10: =D8*(1-D9) -> 409.08776 | E10: =E8*(1-E9) -> 451.36433 | F10: =F8*(1-F9) -> 463.6644 | G10: =G8*(1-G9) -> 472.05828 | H10: =H8*(1-H9) -> 487.63516 | I10: =I8*(1-I9) -> 511.4567 | J10: =J8*(1-J9) -> 535.45902 | ... M10: =M8*(1-M9) -> 589.02616
A11: D&A ($mm) | C11: =C5*Inputs!$B$8 -> 87.1182 | D11: =D5*Inputs!$B$8 -> 263.47643 | E11: =E5*Inputs!$B$8 -> 279.69311 | F11: =F5*Inputs!$B$8 -> 296.90791 | G11: =G5*Inputs!$B$8 -> 315.18225 | H11: =H5*Inputs!$B$8 -> 334.58137 | I11: =I5*Inputs!$B$8 -> 352.72876 | J11: =J5*Inputs!$B$8 -> 369.28208 | ... M11: =M5*Inputs!$B$8 -> 406.22494
A13: The capex derivation — the only block that differs
A14: Fixed capital at valuation date ($mm) | B14: =Inputs!$B$14-Inputs!$B$10*Inputs!$B$5 -> 3213.26 | C14: Invested capital less the working-capital stock
A15: Fixed capital growth (volume + inflation) | D15: =(1+Inputs!C$30)*(1+Inputs!$B$20)/(1+Inputs!$B$19)-1 -> 0.05793641 | E15: =(1+Inputs!D$30)*(1+Inputs!$B$20)/(1+Inputs!$B$19)-1 -> 0.05793641 | F15: =(1+Inputs!E$30)*(1+Inputs!$B$20)/(1+Inputs!$B$19)-1 -> 0.05793641 | G15: =(1+Inputs!F$30)*(1+Inputs!$B$20)/(1+Inputs!$B$19)-1 -> 0.05793641 | H15: =(1+Inputs!G$30)*(1+Inputs!$B$20)/(1+Inputs!$B$19)-1 -> 0.05793641 | I15: =(1+Inputs!H$30)*(1+Inputs!$B$20)/(1+Inputs!$B$19)-1 -> 0.05065151 | J15: =(1+Inputs!I$30)*(1+Inputs!$B$20)/(1+Inputs!$B$19)-1 -> 0.04336661 | K15: =(1+Inputs!J$30)*(1+Inputs!$B$20)/(1+Inputs!$B$19)-1 -> 0.036081711 | ... M15: =(1+Inputs!L$30)*(1+Inputs!$B$20)/(1+Inputs!$B$19)-1 -> 0.021511911 | O15: Strip the pricing rate out of the year's growth, leaving volume; inflate that.
A16: Fixed capital, closing ($mm) | C16: =$B$14+C5*(Inputs!$B$9-Inputs!$B$8) -> 3221.6138 | D16: =C16*(1+D15) -> 3408.2625 | E16: =D16*(1+E15) -> 3605.725 | F16: =E16*(1+F15) -> 3814.6278 | G16: =F16*(1+G15) -> 4035.6336 | H16: =G16*(1+H15) -> 4269.4438 | I16: =H16*(1+I15) -> 4485.6975 | J16: =I16*(1+J15) -> 4680.227 | K16: =J16*(1+K15) -> 4849.0976 | ... M16: =L16*(1+M15) -> 5096.0534
A17: Capex ($mm) | C17: =C5*Inputs!$B$9 -> 95.472 | D17: =D16-C16+D5*Inputs!$B$8 -> 450.12517 | E17: =E16-D16+E5*Inputs!$B$8 -> 477.15561 | F17: =F16-E16+F5*Inputs!$B$8 -> 505.81067 | G17: =G16-F16+G5*Inputs!$B$8 -> 536.1881 | H17: =H16-G16+H5*Inputs!$B$8 -> 568.39149 | I17: =I16-H16+I5*Inputs!$B$8 -> 568.98254 | J17: =J16-I16+J5*Inputs!$B$8 -> 563.81158 | K17: =K16-J16+K5*Inputs!$B$8 -> 552.78347 | ... M17: =M16-L16+M5*Inputs!$B$8 -> 513.54218 | O17: Growth in the asset base, plus replacement of what depreciated.
A18: Capex, % of revenue (implied) | C18: =C17/C5 -> 0.08 | D18: =D17/D5 -> 0.12471376 | E18: =E17/E5 -> 0.12453778 | F18: =F17/F5 -> 0.1243624 | G18: =G17/G5 -> 0.12418761 | H18: =H17/H5 -> 0.12401342 | I18: =I17/I5 -> 0.11775543 | J18: =J17/J5 -> 0.11145476 | ... M18: =M17/M5 -> 0.092285273
A20: Increase in working capital ($mm) | C20: =Inputs!$B$10*(C6-Inputs!$B$5) -> 9.9117529 | D20: =Inputs!$B$10*(D5-C6) -> 18.883273 | E20: =Inputs!$B$10*(E5-D5) -> 30.567328 | F20: =Inputs!$B$10*(F5-E5) -> 32.448712 | G20: =Inputs!$B$10*(G5-F5) -> 34.445894 | H20: =Inputs!$B$10*(H5-G5) -> 36.566 | I20: =Inputs!$B$10*(I5-H5) -> 34.206592 | J20: =Inputs!$B$10*(J5-I5) -> 31.20188 | K20: =Inputs!$B$10*(K5-J5) -> 27.578037 | L20: =Inputs!$B$10*(L5-K5) -> 23.380952 | M20: =Inputs!$B$10*(M5-L5) -> 18.675761
A21: Free cash flow to the firm ($mm) | C21: =C10+C11-C17-C20 -> 112.14323 | D21: =D10+D11-D17-D20 -> 203.55575 | E21: =E10+E11-E17-E20 -> 223.33451 | F21: =F10+F11-F17-F20 -> 222.31292 | G21: =G10+G11-G17-G20 -> 216.60655 | H21: =H10+H11-H17-H20 -> 217.25903 | I21: =I10+I11-I17-I20 -> 260.99633 | J21: =J10+J11-J17-J20 -> 309.72764 | ... M21: =M10+M11-M17-M20 -> 463.03315
A22: Discounting time (mid-year, years) | C22: =Inputs!$B$6/2 -> 0.1755 | D22: =Inputs!$B$6+1-0.5 -> 0.851 | E22: =Inputs!$B$6+2-0.5 -> 1.851 | F22: =Inputs!$B$6+3-0.5 -> 2.851 | G22: =Inputs!$B$6+4-0.5 -> 3.851 | H22: =Inputs!$B$6+5-0.5 -> 4.851 | I22: =Inputs!$B$6+6-0.5 -> 5.851 | J22: =Inputs!$B$6+7-0.5 -> 6.851 | K22: =Inputs!$B$6+8-0.5 -> 7.851 | L22: =Inputs!$B$6+9-0.5 -> 8.851 | M22: =Inputs!$B$6+10-0.5 -> 9.851
A23: Present value of FCFF ($mm) | C23: =C21/(1+Inputs!$B$12)^C22 -> 110.48178 | D23: =D21/(1+Inputs!$B$12)^D22 -> 189.3434 | E23: =E21/(1+Inputs!$B$12)^E22 -> 190.80329 | F23: =F21/(1+Inputs!$B$12)^F22 -> 174.44477 | G23: =G21/(1+Inputs!$B$12)^G22 -> 156.10904 | H23: =H21/(1+Inputs!$B$12)^H22 -> 143.8128 | I23: =I21/(1+Inputs!$B$12)^I22 -> 158.67822 | J23: =J21/(1+Inputs!$B$12)^J22 -> 172.95221 | ... M23: =M21/(1+Inputs!$B$12)^M22 -> 200.33088
A25: Invested capital, rolled forward
A26: Invested capital, closing ($mm) | B26: =Inputs!$B$14 -> 3681.1 | C26: =$B$26+C17-C11+C20 -> 3699.3656 | D26: =C26+D17-D11+D20 -> 3904.8976 | E26: =D26+E17-E11+E20 -> 4132.9274 | F26: =E26+F17-F11+F20 -> 4374.2789 | G26: =F26+G17-G11+G20 -> 4629.7306 | H26: =G26+H17-H11+H20 -> 4900.1067 | I26: =H26+I17-I11+I20 -> 5150.5671 | J26: =I26+J17-J11+J20 -> 5376.2985 | K26: =J26+K17-K11+K20 -> 5572.7471 | ... M26: =L26+M17-M11+M20 -> 5861.7596
A27: Invested capital ÷ revenue | B27: =$B$26/Inputs!$B$5 -> 1.0826765 | D27: =D26/D5 -> 1.081909 | E27: =E26/E5 -> 1.0786955 | F27: =F26/F5 -> 1.0754929 | G27: =G26/G5 -> 1.0723013 | H27: =H26/H5 -> 1.0691205 | I27: =I26/I5 -> 1.0659505 | J27: =J26/J5 -> 1.0627913 | K27: =K26/K5 -> 1.0596429 | ... M27: =M26/M5 -> 1.0533781 | O27: Opening against Y10 is the whole of item 11.
A29: The terminal
A30: Terminal revenue ($mm) | B30: =M5*(1+Inputs!$B$13) -> 5703.8433
A31: Fixed capital at the end of Y10 ($mm) | B31: =M26-Inputs!$B$10*M5 -> 5096.0534
A32: Terminal capex, % of revenue | B32: =Inputs!$B$8+Inputs!$B$13*$B$31/M5 -> 0.095894452 | C32: The rate that grows the fixed base at g forever (D&A plus g times the base).
A33: Terminal FCFF ($mm) | B33: =$B$30*(M7*(1-M9)+Inputs!$B$8-$B$32-Inputs!$B$13*Inputs!$B$10) -> 453.54422
A34: Terminal value ($mm) | B34: =$B$33/(Inputs!$B$12-Inputs!$B$13) -> 7112.0117
A35: Present value of the terminal ($mm) | B35: =$B$34/(1+Inputs!$B$12)^(Inputs!$B$6+10) -> 2948.899
A36: Terminal NOPAT ($mm) | B36: =$B$30*M7*(1-M9) -> 603.75181
A37: Terminal return on invested capital | B37: =$B$36/M26 -> 0.10299839
A38: Terminal ROIC ÷ WACC | B38: =$B$37/Inputs!$B$12 -> 1.1602631 | C38: Above 1.0x is an excess return the build has to defend.
A40: Value
A41: Present value of the explicit period ($mm) | B41: =SUM(C23:M23) -> 1875.6115
A42: Enterprise value ($mm) | B42: =$B$41+$B$35 -> 4824.5105
A43: Terminal share of enterprise value | B43: =$B$35/$B$42 -> 0.61123279 | C43: Above 70% triggers the §11.4.2 sensitivity obligation.
A44: Less net debt ($mm) | B44: =-Inputs!$B$23 -> -1224.0329
A45: Less other bridge adjustments ($mm) | B45: =-Inputs!$B$24 -> -151.65
A46: Less lease liabilities ($mm) | B46: =-Inputs!$B$25 -> -194.3
...

Sheet 4 Volume, held flat
A1: 4 Volume, held flat — Muddle Through
A2: The same basis with the chain's volume rate held for all ten years instead of fading with revenue. This is how the 25 August handover struck it.
A4: Period | C4: Stub | D4: Y1 | E4: Y2 | F4: Y3 | G4: Y4 | H4: Y5 | I4: Y6 | J4: Y7 | K4: Y8 | L4: Y9 | M4: Y10
A5: Revenue ($mm) | C5: =Inputs!$B$5*Inputs!$B$6 -> 1193.4 | D5: =Inputs!$B$5*(1+Inputs!C$30) -> 3609.2662 | E5: =D5*(1+Inputs!D$30) -> 3831.4125 | F5: =E5*(1+Inputs!E$30) -> 4067.2316 | G5: =F5*(1+Inputs!F$30) -> 4317.5651 | H5: =G5*(1+Inputs!G$30) -> 4583.3064 | I5: =H5*(1+Inputs!H$30) -> 4831.9008 | J5: =I5*(1+Inputs!I$30) -> 5058.6587 | K5: =J5*(1+Inputs!J$30) -> 5259.0805 | L5: =K5*(1+Inputs!K$30) -> 5429.0002 | M5: =L5*(1+Inputs!L$30) -> 5564.7252
A6: Revenue run-rate at period end ($mm) | C6: =Inputs!$B$5*(1+Inputs!$C$30)^Inputs!$B$6 -> 3472.0331 | D6: =D5 -> 3609.2662 | E6: =E5 -> 3831.4125 | F6: =F5 -> 4067.2316 | G6: =G5 -> 4317.5651 | H6: =H5 -> 4583.3064 | I6: =I5 -> 4831.9008 | J6: =J5 -> 5058.6587 | K6: =K5 -> 5259.0805 | ... M6: =M5 -> 5564.7252
A7: EBIT margin | C7: =Inputs!$B$7 -> 0.141 | D7: =Inputs!$B$7+Inputs!C$31 -> 0.14625 | E7: =Inputs!$B$7+Inputs!D$31 -> 0.1545 | F7: =Inputs!$B$7+Inputs!E$31 -> 0.152 | G7: =Inputs!$B$7+Inputs!F$31 -> 0.14825 | H7: =Inputs!$B$7+Inputs!G$31 -> 0.14675 | I7: =Inputs!$B$7+Inputs!H$31 -> 0.146 | J7: =Inputs!$B$7+Inputs!I$31 -> 0.146 | K7: =Inputs!$B$7+Inputs!J$31 -> 0.146 | ... M7: =Inputs!$B$7+Inputs!L$31 -> 0.146
A8: EBIT ($mm) | C8: =C5*C7 -> 168.2694 | D8: =D5*D7 -> 527.85518 | E8: =E5*E7 -> 591.95322 | F8: =F5*F7 -> 618.2192 | G8: =G5*G7 -> 640.07903 | H8: =H5*H7 -> 672.60021 | I8: =I5*I7 -> 705.45752 | J8: =J5*J7 -> 738.56417 | ... M8: =M5*M7 -> 812.44987
A9: Tax rate | C9: =Inputs!$B$11 -> 0.225 | D9: =Inputs!C$32 -> 0.225 | E9: =Inputs!D$32 -> 0.2375 | F9: =Inputs!E$32 -> 0.25 | G9: =Inputs!F$32 -> 0.2625 | H9: =Inputs!G$32 -> 0.275 | I9: =Inputs!H$32 -> 0.275 | J9: =Inputs!I$32 -> 0.275 | K9: =Inputs!J$32 -> 0.275 | ... M9: =Inputs!L$32 -> 0.275
A10: NOPAT ($mm) | C10: =C8*(1-C9) -> 130.40878 | D10: =D8*(1-D9) -> 409.08776 | E10: =E8*(1-E9) -> 451.36433 | F10: =F8*(1-F9) -> 463.6644 | G10: =G8*(1-G9) -> 472.05828 | H10: =H8*(1-H9) -> 487.63516 | I10: =I8*(1-I9) -> 511.4567 | J10: =J8*(1-J9) -> 535.45902 | ... M10: =M8*(1-M9) -> 589.02616
A11: D&A ($mm) | C11: =C5*Inputs!$B$8 -> 87.1182 | D11: =D5*Inputs!$B$8 -> 263.47643 | E11: =E5*Inputs!$B$8 -> 279.69311 | F11: =F5*Inputs!$B$8 -> 296.90791 | G11: =G5*Inputs!$B$8 -> 315.18225 | H11: =H5*Inputs!$B$8 -> 334.58137 | I11: =I5*Inputs!$B$8 -> 352.72876 | J11: =J5*Inputs!$B$8 -> 369.28208 | ... M11: =M5*Inputs!$B$8 -> 406.22494
A13: The capex derivation — the only block that differs
A14: Fixed capital at valuation date ($mm) | B14: =Inputs!$B$14-Inputs!$B$10*Inputs!$B$5 -> 3213.26 | C14: Invested capital less the working-capital stock
A15: Fixed capital growth (chain volume + inflation) | D15: =(1+Inputs!$B$18)*(1+Inputs!$B$20)-1 -> 0.05856875 | E15: =(1+Inputs!$B$18)*(1+Inputs!$B$20)-1 -> 0.05856875 | F15: =(1+Inputs!$B$18)*(1+Inputs!$B$20)-1 -> 0.05856875 | G15: =(1+Inputs!$B$18)*(1+Inputs!$B$20)-1 -> 0.05856875 | H15: =(1+Inputs!$B$18)*(1+Inputs!$B$20)-1 -> 0.05856875 | I15: =(1+Inputs!$B$18)*(1+Inputs!$B$20)-1 -> 0.05856875 | J15: =(1+Inputs!$B$18)*(1+Inputs!$B$20)-1 -> 0.05856875 | K15: =(1+Inputs!$B$18)*(1+Inputs!$B$20)-1 -> 0.05856875 | ... M15: =(1+Inputs!$B$18)*(1+Inputs!$B$20)-1 -> 0.05856875
A16: Fixed capital, closing ($mm) | C16: =$B$14+C5*(Inputs!$B$9-Inputs!$B$8) -> 3221.6138 | D16: =C16*(1+D15) -> 3410.2997 | E16: =D16*(1+E15) -> 3610.0367 | F16: =E16*(1+F15) -> 3821.472 | G16: =F16*(1+G15) -> 4045.2909 | H16: =G16*(1+H15) -> 4282.2185 | I16: =H16*(1+I15) -> 4533.0227 | J16: =I16*(1+J15) -> 4798.5161 | K16: =J16*(1+K15) -> 5079.5592 | ... M16: =L16*(1+M15) -> 5691.9905
A17: Capex ($mm) | C17: =C5*Inputs!$B$9 -> 95.472 | D17: =D16-C16+D5*Inputs!$B$8 -> 452.16232 | E17: =E16-D16+E5*Inputs!$B$8 -> 479.4301 | F17: =F16-E16+F5*Inputs!$B$8 -> 508.34324 | G17: =G16-F16+G5*Inputs!$B$8 -> 539.00109 | H17: =H16-G16+H5*Inputs!$B$8 -> 571.509 | I17: =I16-H16+I5*Inputs!$B$8 -> 603.53294 | J17: =J16-I16+J5*Inputs!$B$8 -> 634.77555 | K17: =K16-J16+K5*Inputs!$B$8 -> 664.95597 | ... M17: =M16-L16+M5*Inputs!$B$8 -> 721.15278 | O17: Growth in the asset base, plus replacement of what depreciated.
A18: Capex, % of revenue (implied) | C18: =C17/C5 -> 0.08 | D18: =D17/D5 -> 0.12527819 | E18: =E17/E5 -> 0.12513142 | F18: =F17/F5 -> 0.12498507 | G18: =G17/G5 -> 0.12483913 | H18: =H17/H5 -> 0.1246936 | I18: =I17/I5 -> 0.1249059 | J18: =J17/J5 -> 0.12548298 | ... M18: =M17/M5 -> 0.1295936
A20: Increase in working capital ($mm) | C20: =Inputs!$B$10*(C6-Inputs!$B$5) -> 9.9117529 | D20: =Inputs!$B$10*(D5-C6) -> 18.883273 | E20: =Inputs!$B$10*(E5-D5) -> 30.567328 | F20: =Inputs!$B$10*(F5-E5) -> 32.448712 | G20: =Inputs!$B$10*(G5-F5) -> 34.445894 | H20: =Inputs!$B$10*(H5-G5) -> 36.566 | I20: =Inputs!$B$10*(I5-H5) -> 34.206592 | J20: =Inputs!$B$10*(J5-I5) -> 31.20188 | K20: =Inputs!$B$10*(K5-J5) -> 27.578037 | L20: =Inputs!$B$10*(L5-K5) -> 23.380952 | M20: =Inputs!$B$10*(M5-L5) -> 18.675761
A21: Free cash flow to the firm ($mm) | C21: =C10+C11-C17-C20 -> 112.14323 | D21: =D10+D11-D17-D20 -> 201.5186 | E21: =E10+E11-E17-E20 -> 221.06002 | F21: =F10+F11-F17-F20 -> 219.78035 | G21: =G10+G11-G17-G20 -> 213.79355 | H21: =H10+H11-H17-H20 -> 214.14153 | I21: =I10+I11-I17-I20 -> 226.44593 | J21: =J10+J11-J17-J20 -> 238.76367 | ... M21: =M10+M11-M17-M20 -> 255.42256
A22: Discounting time (mid-year, years) | C22: =Inputs!$B$6/2 -> 0.1755 | D22: =Inputs!$B$6+1-0.5 -> 0.851 | E22: =Inputs!$B$6+2-0.5 -> 1.851 | F22: =Inputs!$B$6+3-0.5 -> 2.851 | G22: =Inputs!$B$6+4-0.5 -> 3.851 | H22: =Inputs!$B$6+5-0.5 -> 4.851 | I22: =Inputs!$B$6+6-0.5 -> 5.851 | J22: =Inputs!$B$6+7-0.5 -> 6.851 | K22: =Inputs!$B$6+8-0.5 -> 7.851 | L22: =Inputs!$B$6+9-0.5 -> 8.851 | M22: =Inputs!$B$6+10-0.5 -> 9.851
A23: Present value of FCFF ($mm) | C23: =C21/(1+Inputs!$B$12)^C22 -> 110.48178 | D23: =D21/(1+Inputs!$B$12)^D22 -> 187.44848 | E23: =E21/(1+Inputs!$B$12)^E22 -> 188.8601 | F23: =F21/(1+Inputs!$B$12)^F22 -> 172.45751 | G23: =G21/(1+Inputs!$B$12)^G22 -> 154.08171 | H23: =H21/(1+Inputs!$B$12)^H22 -> 141.74919 | I23: =I21/(1+Inputs!$B$12)^I22 -> 137.67258 | J23: =J21/(1+Inputs!$B$12)^J22 -> 133.32586 | ... M23: =M21/(1+Inputs!$B$12)^M22 -> 110.50834
A25: Invested capital, rolled forward
A26: Invested capital, closing ($mm) | B26: =Inputs!$B$14 -> 3681.1 | C26: =$B$26+C17-C11+C20 -> 3699.3656 | D26: =C26+D17-D11+D20 -> 3906.9347 | E26: =D26+E17-E11+E20 -> 4137.239 | F26: =E26+F17-F11+F20 -> 4381.1231 | G26: =F26+G17-G11+G20 -> 4639.3878 | H26: =G26+H17-H11+H20 -> 4912.8814 | I26: =H26+I17-I11+I20 -> 5197.8922 | J26: =I26+J17-J11+J20 -> 5494.5876 | K26: =J26+K17-K11+K20 -> 5803.2087 | ... M26: =L26+M17-M11+M20 -> 6457.6967
A27: Invested capital ÷ revenue | B27: =$B$26/Inputs!$B$5 -> 1.0826765 | D27: =D26/D5 -> 1.0824734 | E27: =E26/E5 -> 1.0798208 | F27: =F26/F5 -> 1.0771757 | G27: =G26/G5 -> 1.074538 | H27: =H26/H5 -> 1.0719077 | I27: =I26/I5 -> 1.0757448 | J27: =J26/J5 -> 1.0861748 | K27: =K26/K5 -> 1.1034645 | ... M27: =M26/M5 -> 1.16047 | O27: Opening against Y10 is the whole of item 11.
A29: The terminal
A30: Terminal revenue ($mm) | B30: =M5*(1+Inputs!$B$13) -> 5703.8433
A31: Fixed capital at the end of Y10 ($mm) | B31: =M26-Inputs!$B$10*M5 -> 5691.9905
A32: Terminal capex, % of revenue | B32: =Inputs!$B$8+Inputs!$B$13*$B$31/M5 -> 0.09857175 | C32: The rate that grows the fixed base at g forever (D&A plus g times the base).
A33: Terminal FCFF ($mm) | B33: =$B$30*(M7*(1-M9)+Inputs!$B$8-$B$32-Inputs!$B$13*Inputs!$B$10) -> 438.27333
A34: Terminal value ($mm) | B34: =$B$33/(Inputs!$B$12-Inputs!$B$13) -> 6872.5495
A35: Present value of the terminal ($mm) | B35: =$B$34/(1+Inputs!$B$12)^(Inputs!$B$6+10) -> 2849.6092
A36: Terminal NOPAT ($mm) | B36: =$B$30*M7*(1-M9) -> 603.75181
A37: Terminal return on invested capital | B37: =$B$36/M26 -> 0.093493368
A38: Terminal ROIC ÷ WACC | B38: =$B$37/Inputs!$B$12 -> 1.0531903 | C38: Above 1.0x is an excess return the build has to defend.
A40: Value
A41: Present value of the explicit period ($mm) | B41: =SUM(C23:M23) -> 1583.3473
A42: Enterprise value ($mm) | B42: =$B$41+$B$35 -> 4432.9565
A43: Terminal share of enterprise value | B43: =$B$35/$B$42 -> 0.64282364 | C43: Above 70% triggers the §11.4.2 sensitivity obligation.
A44: Less net debt ($mm) | B44: =-Inputs!$B$23 -> -1224.0329
A45: Less other bridge adjustments ($mm) | B45: =-Inputs!$B$24 -> -151.65
A46: Less lease liabilities ($mm) | B46: =-Inputs!$B$25 -> -194.3
...

Sheet Comparison
A1: The four positions, side by side
A2: Muddle Through. Every figure is a live link to the sheet named above it.
B4: 1 Ruled build | C4: 2 Hold intensity | D4: 3 Volume + inflation | E4: 4 Volume, held flat
A5: Value per share ($) | B5: ='1 Ruled build'!$B$46 -> 2.6956169 | C5: ='2 Hold intensity'!$B$49 -> 1.767565 | D5: ='3 Volume + inflation'!$B$48 -> 1.8387162 | E5: ='4 Volume, held flat'!$B$48 -> 1.6174992
A7: Invested capital ÷ revenue, Y10 | B7: ='1 Ruled build'!M25 -> 0.7261916 | C7: ='2 Hold intensity'!M28 -> 1.0826765 | D7: ='3 Volume + inflation'!M27 -> 1.0533781 | E7: ='4 Volume, held flat'!M27 -> 1.16047 | G7: Opens at 108.3% in every position
A8: Terminal capex, % of revenue | B8: ='1 Ruled build'!$B$30 -> 0.08771479 | C8: ='2 Hold intensity'!$B$33 -> 0.096626912 | D8: ='3 Volume + inflation'!$B$32 -> 0.095894452 | E8: ='4 Volume, held flat'!$B$32 -> 0.09857175
A9: Terminal return on invested capital | B9: ='1 Ruled build'!$B$35 -> 0.14940444 | C9: ='2 Hold intensity'!$B$38 -> 0.10021115 | D9: ='3 Volume + inflation'!$B$37 -> 0.10299839 | E9: ='4 Volume, held flat'!$B$37 -> 0.093493368 | G9: WACC is 8.88%
A10: Terminal ROIC ÷ WACC | B10: ='1 Ruled build'!$B$36 -> 1.6830211 | C10: ='2 Hold intensity'!$B$39 -> 1.1288652 | D10: ='3 Volume + inflation'!$B$38 -> 1.1602631 | E10: ='4 Volume, held flat'!$B$38 -> 1.0531903 | G10: Above 1.0x needs a defence
A11: Terminal share of enterprise value | B11: ='1 Ruled build'!$B$41 -> 0.51287387 | C11: ='2 Hold intensity'!$B$44 -> 0.62183459 | D11: ='3 Volume + inflation'!$B$43 -> 0.61123279 | E11: ='4 Volume, held flat'!$B$43 -> 0.64282364 | G11: Above 70% triggers §11.4.2
A13: Against the current published level of $2.6956 | B13: ='1 Ruled build'!$B$46/'1 Ruled build'!$B$46-1 -> 0 | C13: ='2 Hold intensity'!$B$49/'1 Ruled build'!$B$46-1 -> -0.34428182 | D13: ='3 Volume + inflation'!$B$48/'1 Ruled build'!$B$46-1 -> -0.31788668 | E13: ='4 Volume, held flat'!$B$48/'1 Ruled build'!$B$46-1 -> -0.39995211

Sheet Six scenarios
A1: All six scenarios, each position
A2: Computed in the repository harness (scripts/size_horizon_variants.py), not in this workbook. Only Muddle Through is built out cell by cell here.
A4: Scenario | B4: 1 Ruled build | C4: 2 Hold intensity | D4: 3 Volume + inflation | E4: 4 Volume, held flat
A5: Orderly Convergence | B5: 3.1793235 | C5: 1.9804438 | D5: 1.8670831 | E5: 1.5341774
A6: Muddle Through | B6: 2.6956169 | C6: 1.767565 | D6: 1.8387162 | E6: 1.6174992
A7: Ai Productivity Lag | B7: 2.6558218 | C7: 1.862962 | D7: 1.9801322 | E7: 1.7956994
A8: Fragmentation | B8: 1.8629226 | C8: 0.949706 | D8: 1.3304625 | E8: 1.1264408
A9: Disorderly Climate | B9: 1.5294107 | C9: 0.94853945 | D9: 1.5334827 | E9: 1.2763624
A10: Stagflation Persists | B10: 0.5840919 | C10: -0.19975471 | D10: 0.3307895 | E10: 0.18490978
A12: Disorderly Climate is the exception: its capex arc, not the convergence rule, sets its path, so the positions collapse together there.
