Workbook

Sheet Cover
A1: CSL Limited (ASX:CSL)
A2: Muddle Through valuation v1 — segment-level (Behring + Seqirus + Vifor + corporate), USD model
A3: 18 June 2026 | Reid Advisory
A5: Headline result
A6: Value per share USD | B6: ='Per-Share Value'!C33
A7: Spot AUD/USD | B7: 0.66
A8: Value per share AUD | B8: =B6/B7
A9: Market reference AUD (15 June 2026) | B9: 105.53
A10: vs market | B10: =B8/B9-1
A11: Sell-side consensus 12-month target AUD | B11: 138.58
A13: Workbook conventions
A14: • Yellow-shaded cells with blue text on the Assumptions sheet are INPUTS — change these to flex the model.
A15: • All other cells are formulas. Trace any output to its formula via the formula bar.
A16: • USD throughout for cash flows, discount rate, equity value. AUD translation only at the per-share comparison step on this Cover sheet.
A17: • Anchor period: FY26 (year ending 30 June 2026) — based on 1H26 actuals + 2H26 implied by FY26 guidance.
A18: • Segment-level: Behring + Seqirus + Vifor + Corporate, aggregated to consolidated NPATA → FCFF → per share.
A19: • Peer-gap closure overlay: per management's USD 525m annual pre-tax savings target by FY27. Stated mechanism: Strategic Transformation (FY25 results presentation slide 19).
A20: • Restructuring execution cash USD 525m face / USD 507m PV deducted in equity bridge per §4.4(b). Tax shield already absorbed in trailing book equity (1H26 charge).

Sheet Assumptions
A1: Muddle Through assumptions — INPUT LAYER (yellow cells are inputs)
A3: FY25 actuals (anchor year ending 30 June 2025) — USD m
A4: Group Revenue FY25 | B4: 15558
A5: Group NPATA FY25 | B5: 3219
A6: Group R&D FY25 (in opex) | B6: 1359
A7: FY25 R&D as % of revenue (memo) | B7: =1359/Assumptions!$B$4
A9: Segment FY25 revenue (USD m) — split of group
A10: CSL Behring revenue FY25 | B10: 11158
A11: CSL Seqirus revenue FY25 | B11: 2166
A12: CSL Vifor revenue FY25 | B12: 2234
A13: Sum check (should equal Group) | B13: =Assumptions!$B$10+Assumptions!$B$11+Assumptions!$B$12
A15: Segment FY25 operating-result margins (per FY25 results pres p.16-17)
A16: CSL Behring OR margin FY25 | B16: 0.422
A17: CSL Seqirus OR margin FY25 | B17: 0.474
A18: CSL Vifor OR margin FY25 | B18: 0.491
A20: Segment growth assumptions (Muddle Through CAGR, FY26-FY31)
A21: Behring revenue CAGR (Muddle Through) | B21: 0.05 | C21: v3: superseded by Behring J-curve vector below (rows 69-74)
A22: Seqirus revenue CAGR | B22: 0.02 | C22: Mature seasonal vaccine market
A23: Vifor revenue CAGR | B23: 0.07 | C23: FY25 +8%; 1H26 +12% on indication expansion
A25: Peer-gap closure overlay — segment margin uplift per Strategic Transformation
A26: Behring margin uplift (cumulative bps by FY31) | B26: 0.015 | C26: v3: phased — full +250bps reserved for Orderly Convergence; +150bps in Muddle Through
A27: Seqirus margin uplift (cumulative bps by FY31) | B27: 0.01
A28: Vifor margin uplift (cumulative bps by FY31) | B28: 0.01
A30: Corporate items
A31: R&D + G&A + central FY25 (negative) | B31: -2559 | C31: FY25 R&D 1,359 + G&A 1,000 + other 200
A32: Net interest expense FY26 (estimate) | B32: -390 | C32: FY25 actual (410); reducing as debt paid down
A33: Effective tax rate | B33: 0.19 | C33: FY26 guidance 18-20%
A35: Capital allocation
A36: Capex / revenue ratio | B36: 0.045 | C36: FY26 guidance ~USD 800m; steady ~5% of revenue
A37: D&A / revenue ratio | B37: 0.06
A38: Working capital change / revenue change ratio | B38: 0.1
A39: Dividend payout ratio (NPATA basis) | B39: 0.44 | C39: FY25 actual: DPS 2.92 / NPATA EPS 6.65 = 44%
A41: Cost of equity build (per §15.2 + §3.5.3 peer-triangulation)
A42: Risk-free rate (10y US Treasury) | B42: 0.045 | C42: USD anchor; 10y US Treasury yield mid-2026
A43: Equity risk premium | B43: 0.05 | C43: Damodaran-style mature-market ERP
A44: Beta measured (EODHD) | B44: 0.094 | C44: UNRELIABLE — USD revenue base vs AUD ASX series
A45: Beta selected (peer-triangulated) | B45: 0.85 | C45: Defensive healthcare franchise; peers Grifols / Takeda / Sanofi 0.7-0.9
A46: equals Cost of equity Re (derived) | B46: =Assumptions!$B$42+Assumptions!$B$45*Assumptions!$B$43
A48: Balance sheet anchors (FY25 close + 1H26 close)
A49: Net debt at 1H26 close (USD m) | B49: 9100 | C49: FY25 leverage 1.8x EBITDA, EBITDA ~$5.05bn
...

Sheet Segment Forecasts
A1: Per-segment revenue + operating result forecast (USD m)
A2: FY25 base anchored to disclosed segment financials. Growth + margin uplift applied per Assumptions sheet.
A4: Line | B4: FY25 actual | C4: FY26 | D4: FY27 | E4: FY28 | F4: FY29 | G4: FY30 | H4: FY31
A5: CSL BEHRING
A6: Revenue | B6: =Assumptions!$B$10 | C6: =B6*(1+Assumptions!$B$69) | D6: =C6*(1+Assumptions!$B$70) | E6: =D6*(1+Assumptions!$B$71) | F6: =E6*(1+Assumptions!$B$72) | G6: =F6*(1+Assumptions!$B$73) | H6: =G6*(1+Assumptions!$B$74)
A7: Operating result margin | B7: =Assumptions!$B$16 | C7: =Assumptions!$B$16+Assumptions!$B$26*(1/6) | D7: =Assumptions!$B$16+Assumptions!$B$26*(2/6) | E7: =Assumptions!$B$16+Assumptions!$B$26*(3/6) | F7: =Assumptions!$B$16+Assumptions!$B$26*(4/6) | G7: =Assumptions!$B$16+Assumptions!$B$26*(5/6) | H7: =Assumptions!$B$16+Assumptions!$B$26*(6/6)
A8: Operating result | B8: =B6*B7 | C8: =C6*C7 | D8: =D6*D7 | E8: =E6*E7 | F8: =F6*F7 | G8: =G6*G7 | H8: =H6*H7
A10: CSL SEQIRUS
A11: Revenue | B11: =Assumptions!$B$11 | C11: =B11*(1+Assumptions!$B$22) | D11: =C11*(1+Assumptions!$B$22) | E11: =D11*(1+Assumptions!$B$22) | F11: =E11*(1+Assumptions!$B$22) | G11: =F11*(1+Assumptions!$B$22) | H11: =G11*(1+Assumptions!$B$22)
A12: Operating result margin | B12: =Assumptions!$B$17 | C12: =Assumptions!$B$17+Assumptions!$B$27*(1/6) | D12: =Assumptions!$B$17+Assumptions!$B$27*(2/6) | E12: =Assumptions!$B$17+Assumptions!$B$27*(3/6) | F12: =Assumptions!$B$17+Assumptions!$B$27*(4/6) | G12: =Assumptions!$B$17+Assumptions!$B$27*(5/6) | H12: =Assumptions!$B$17+Assumptions!$B$27*(6/6)
A13: Operating result | B13: =B11*B12 | C13: =C11*C12 | D13: =D11*D12 | E13: =E11*E12 | F13: =F11*F12 | G13: =G11*G12 | H13: =H11*H12
A15: CSL VIFOR
A16: Revenue | B16: =Assumptions!$B$12 | C16: =B16*(1+Assumptions!$B$23) | D16: =C16*(1+Assumptions!$B$23) | E16: =D16*(1+Assumptions!$B$23) | F16: =E16*(1+Assumptions!$B$23) | G16: =F16*(1+Assumptions!$B$23) | H16: =G16*(1+Assumptions!$B$23)
A17: Operating result margin | B17: =Assumptions!$B$18 | C17: =Assumptions!$B$18+Assumptions!$B$28*(1/6) | D17: =Assumptions!$B$18+Assumptions!$B$28*(2/6) | E17: =Assumptions!$B$18+Assumptions!$B$28*(3/6) | F17: =Assumptions!$B$18+Assumptions!$B$28*(4/6) | G17: =Assumptions!$B$18+Assumptions!$B$28*(5/6) | H17: =Assumptions!$B$18+Assumptions!$B$28*(6/6)
A18: Operating result | B18: =B16*B17 | C18: =C16*C17 | D18: =D16*D17 | E18: =E16*E17 | F18: =F16*F17 | G18: =G16*G17 | H18: =H16*H17
A20: GROUP ROLLUP
A21: Total revenue (sum of segments) | B21: =B6+B11+B16 | C21: =C6+C11+C16 | D21: =D6+D11+D16 | E21: =E6+E11+E16 | F21: =F6+F11+F16 | G21: =G6+G11+G16 | H21: =H6+H11+H16
A22: Segment operating result (sum) | B22: =B8+B13+B18 | C22: =C8+C13+C18 | D22: =D8+D13+D18 | E22: =E8+E13+E18 | F22: =F8+F13+F18 | G22: =G8+G13+G18 | H22: =H8+H13+H18
A23: Less: corporate / unallocated | B23: =Assumptions!$B$31 | C23: =B23*1.005 | D23: =C23*1.005 | E23: =D23*1.005 | F23: =E23*1.005 | G23: =F23*1.005 | H23: =G23*1.005
A24: Group EBIT | B24: =B22+B23 | C24: =C22+C23 | D24: =D22+D23 | E24: =E22+E23 | F24: =F22+F23 | G24: =G22+G23 | H24: =H22+H23
A25: Group EBIT margin (memo) | B25: =B24/B21 | C25: =C24/C21 | D25: =D24/D21 | E25: =E24/E21 | F25: =F24/F21 | G25: =G24/G21 | H25: =H24/H21
A26: Net interest expense | B26: =Assumptions!$B$32*1.05 | C26: =B26*0.95 | D26: =C26*0.95 | E26: =D26*0.95 | F26: =E26*0.95 | G26: =F26*0.95 | H26: =G26*0.95
A27: Profit before tax | B27: =B24+B26 | C27: =C24+C26 | D27: =D24+D26 | E27: =E24+E26 | F27: =F24+F26 | G27: =G24+G26 | H27: =H24+H26
A28: Income tax expense | B28: =-B27*Assumptions!$B$33 | C28: =-C27*Assumptions!$B$33 | D28: =-D27*Assumptions!$B$33 | E28: =-E27*Assumptions!$B$33 | F28: =-F27*Assumptions!$B$33 | G28: =-G27*Assumptions!$B$33 | H28: =-H27*Assumptions!$B$33
A29: NPATA | B29: =B27+B28 | C29: =C27+C28 | D29: =D27+D28 | E29: =E27+E28 | F29: =F27+F28 | G29: =G27+G28 | H29: =H27+H28

Sheet Per-Share Value
A1: Per-share value — FCFF DCF + equity bridge
A2: Discount rate Re from Assumptions. Mid-period discounting. USD throughout; AUD only at Cover sheet output.
A4: Line | B4: FY26 | C4: FY27 | D4: FY28 | E4: FY29 | F4: FY30 | G4: FY31
A5: Group EBIT (from Segment Forecasts) | B5: ='Segment Forecasts'!C24 | C5: ='Segment Forecasts'!D24 | D5: ='Segment Forecasts'!E24 | E5: ='Segment Forecasts'!F24 | F5: ='Segment Forecasts'!G24 | G5: ='Segment Forecasts'!H24
A6: Group Revenue (from Segment Forecasts) | B6: ='Segment Forecasts'!C21 | C6: ='Segment Forecasts'!D21 | D6: ='Segment Forecasts'!E21 | E6: ='Segment Forecasts'!F21 | F6: ='Segment Forecasts'!G21 | G6: ='Segment Forecasts'!H21
A7: Less: tax on EBIT | B7: =-B5*Assumptions!$B$33 | C7: =-C5*Assumptions!$B$33 | D7: =-D5*Assumptions!$B$33 | E7: =-E5*Assumptions!$B$33 | F7: =-F5*Assumptions!$B$33 | G7: =-G5*Assumptions!$B$33
A8: NOPAT | B8: =B5+B7 | C8: =C5+C7 | D8: =D5+D7 | E8: =E5+E7 | F8: =F5+F7 | G8: =G5+G7
A9: Plus: D&A | B9: =B6*Assumptions!$B$37 | C9: =C6*Assumptions!$B$37 | D9: =D6*Assumptions!$B$37 | E9: =E6*Assumptions!$B$37 | F9: =F6*Assumptions!$B$37 | G9: =G6*Assumptions!$B$37
A10: Less: capex | B10: =-B6*Assumptions!$B$36 | C10: =-C6*Assumptions!$B$36 | D10: =-D6*Assumptions!$B$36 | E10: =-E6*Assumptions!$B$36 | F10: =-F6*Assumptions!$B$36 | G10: =-G6*Assumptions!$B$36
A11: Less: working capital change | B11: =-(B6-Assumptions!$B$4)*Assumptions!$B$38 | C11: =-(C6-B6)*Assumptions!$B$38 | D11: =-(D6-C6)*Assumptions!$B$38 | E11: =-(E6-D6)*Assumptions!$B$38 | F11: =-(F6-E6)*Assumptions!$B$38 | G11: =-(G6-F6)*Assumptions!$B$38
A12: Free cash flow to firm (FCFF) | B12: =B8+B9+B10+B11 | C12: =C8+C9+C10+C11 | D12: =D8+D9+D10+D11 | E12: =E8+E9+E10+E11 | F12: =F8+F9+F10+F11 | G12: =G8+G9+G10+G11
A14: Mid-period time (years) | B14: 0 | C14: 0.5 | D14: 1.5 | E14: 2.5 | F14: 3.5 | G14: 4.5
A15: Discount factor | B15: =1/(1+Assumptions!$B$46)^B14 | C15: =1/(1+Assumptions!$B$46)^C14 | D15: =1/(1+Assumptions!$B$46)^D14 | E15: =1/(1+Assumptions!$B$46)^E14 | F15: =1/(1+Assumptions!$B$46)^F14 | G15: =1/(1+Assumptions!$B$46)^G14
A16: PV of FCFF (FY27-FY31 explicit + FY26 if appropriate) | B16: 0 | C16: =C12*C15 | D16: =D12*D15 | E16: =E12*E15 | F16: =F12*F15 | G16: =G12*G15
A17: Sum of explicit PV (FY27-FY31) | C17: =SUM(C16:G16)
A19: Terminal value
A20: Terminal FCFF (normalised: FY31 rev x terminal EBIT margin) x (1+g) | C20: =(G6*Assumptions!$B$55*(1-Assumptions!$B$33)+G9+G10-(G6*Assumptions!$B$54)*Assumptions!$B$38)*(1+Assumptions!$B$54)
A21: Terminal value (Gordon growth) | C21: =$C$20/(Assumptions!$B$46-Assumptions!$B$54)
A22: Discount factor at end Y5 (t=5) | C22: =1/(1+Assumptions!$B$46)^5
A23: PV of terminal value | C23: =$C$21*$C$22
A25: Equity bridge per §4 (FCFF to per share)
A26: Sum of PV explicit FCFF (FY27-FY31) | C26: =$C$17
A27: Plus: PV of terminal value | C27: =$C$23
A28: Enterprise value | C28: =$C$17+$C$23
A29: Less: net debt at anchor | C29: =-Assumptions!$B$49
A30: Less: restructuring cash to come (PV per §4.4(b)) | C30: =-Assumptions!$B$50
A31: Equity value | C31: =$C$28-Assumptions!$B$49-Assumptions!$B$50
A32: ÷ Shares outstanding (m) | C32: =Assumptions!$B$51
A33: Value per share USD | C33: =$C$31/Assumptions!$B$51

Sheet Sources
A1: Source documents per §14
A3: Anchor | B3: Value | C3: Source
A4: Group Revenue FY25 | B4: USD 15,558m | C4: FY25 results presentation p.15
A5: Group NPATA FY25 | B5: USD 3,219m | C5: FY25 results presentation p.15
A6: Behring revenue FY25 | B6: USD 11,158m | C6: FY25 results presentation p.16
A7: Seqirus revenue FY25 | B7: USD 2,166m | C7: FY25 results presentation p.17
A8: Vifor revenue FY25 | B8: USD 2,234m | C8: FY25 results presentation p.17
A9: Behring OR margin FY25 | B9: 42.2% | C9: FY25 results presentation p.16
A10: Seqirus OR margin FY25 | B10: 47.4% | C10: FY25 results presentation p.17
A11: Vifor OR margin FY25 | B11: 49.1% | C11: FY25 results presentation p.17
A12: Restructuring pre-tax (FY26) | B12: USD 700-770m | C12: FY25 results presentation p.20 footnote
A13: Restructuring cash (FY26 + FY27) | B13: USD 525m total | C13: FY25 results presentation p.20 footnote
A14: Tax shield on 1H26 charge | B14: USD 403m / 22% effective | C14: 1H26 statutory accounts; results pres p.15
... A20: Effective tax rate | B20: 19% | C20: FY26 guidance 18-20% (FY25 actual 15.9%, post-tax-rate-change Pillar 2)

Sheet Consensus comparison
A1: Framework (Muddle Through) vs sell-side consensus — USD m unless noted
A2: Model cells link to Segment Forecasts / Per-Share Value. Consensus cells link to Assumptions inputs. Differences are formulas.
A4: Line | B4: FY26 | C4: FY27 | D4: FY28
A5: Group revenue (USD m)
A6: Framework | B6: ='Segment Forecasts'!C21 | C6: ='Segment Forecasts'!D21 | D6: ='Segment Forecasts'!E21
A7: Consensus | B7: =Assumptions!$B$58 | C7: =Assumptions!$B$59 | D7: =Assumptions!$B$60
A8: Difference (framework vs cons) | B8: =B6/B7-1 | C8: =C6/C7-1 | D8: =D6/D7-1
A10: Group EBIT (USD m)
A11: Framework | B11: ='Segment Forecasts'!C24 | C11: ='Segment Forecasts'!D24 | D11: ='Segment Forecasts'!E24
A12: Consensus | B12: =Assumptions!$B$61 | C12: =Assumptions!$B$62 | D12: =Assumptions!$B$63
A13: Difference (framework vs cons) | B13: =B11/B12-1 | C13: =C11/C12-1 | D13: =D11/D12-1
A15: NPATA EPS (USD)
A16: Framework | B16: ='Segment Forecasts'!C29/Assumptions!$B$51 | C16: ='Segment Forecasts'!D29/Assumptions!$B$51 | D16: ='Segment Forecasts'!E29/Assumptions!$B$51
A17: Consensus | B17: =Assumptions!$B$64 | C17: =Assumptions!$B$65
A18: Difference (framework vs cons) | B18: =B16/B17-1 | C18: =C16/C17-1
A20: Per-share value vs market
A21: Framework Muddle Through (USD/share) | B21: ='Per-Share Value'!C33
A22: Consensus 12m target (USD/share) | B22: =Assumptions!$B$66
A23: Framework premium to consensus target | B23: =B21/B22-1
A25: Read-through
A26: • Framework is ABOVE consensus on revenue (+6% to +10%) and EBIT (+4% to +17%); gap widens through FY28.
A27: • Direction differs, not just degree: consensus FY26 revenue -1.1% and normalised EPS -5%; framework +4.9% / +7-10%.
A28: • Consensus cut hard recently (FY26 EPS 6.90 -> 6.28 over 90 days; 15 downward revisions, 0 up).
A29: • Near-term divergence driven by Behring 5% CAGR + peer-gap-closure margin uplift; terminal block amplifies into per-share.
