Workbook

Sheet Cover
A1: Westpac Banking Corporation (ASX:WBC)
A2: Muddle Through valuation v4 — formula-based (Tara standing rule)
A3: 17 June 2026 | Reid Advisory
A5: Headline result
A6: Per share value (Muddle Through) | B6: ='Per-Share Value'!C40
A7: Market reference (15 June 2026) | B7: 35.32
A8: Discount / (premium) vs market | B8: =B6/B7-1
A10: Workbook conventions
A11: • Yellow-shaded cells: input assumptions — change these to flex the model.
A12: • Blue text cells: input cells (cross-cutting).
A13: • All other cells: formulas linked to Assumptions sheet or other tabs.
A14: • Trace any output back to inputs by clicking the cell and viewing the formula bar.

Sheet Assumptions
A1: Muddle Through assumptions — INPUT LAYER (yellow cells are inputs)
A3: Industry-archetype anchors (per Section 3 of discussion document)
A4: Industry AIEA growth p.a. (Muddle Through) | B4: 0.045 | C4: Big Four system credit growth
A5: Industry NIM anchor | B5: 0.0186 | C5: Big Four through-cycle average
A7: WBC company-position offsets (Five Forces)
A8: WBC AIEA growth offset (Five Forces drag) | B8: -0.0015 | C8: Rivalry -10bps + biz banking rebuild -5bps
A9: WBC NIM offset (supplier power: deposit franchise) | B9: 0.0008 | C9: +8bps from non-interest-bearing transaction balances
A10: equals WBC AIEA growth (derived) | B10: =Assumptions!$B$4+Assumptions!$B$8
A11: equals WBC NIM anchor (derived) | B11: =Assumptions!$B$5+Assumptions!$B$9
A13: 1H26 actuals (income anchors, AUD m)
A14: Net interest income 1H26 ex Notable | B14: 9763
A15: Non-interest income 1H26 ex Notable | B15: 1521
A16: Operating expenses 1H26 ex Notable | B16: 5830
A17: Credit impairment charges 1H26 | B17: 443
A18: Cash NPAT 1H26 ex Notable | B18: 3483
A20: Balance sheet anchors (31 March 2026, AUD m)
A21: Average interest-earning assets (1H26 avg) | B21: 1035226
A22: Book equity total (1H26 close) | B22: 72825
A23: AT1 hybrid outstanding | B23: 8522
A24: Non-controlling interests (book) | B24: 350
A25: Treasury shares (book) | B25: 64
A26: Shares outstanding (m) | B26: 3414.9
A28: Forecast drivers
A29: Non-NII growth p.a. | B29: 0.025
A30: Through-cycle credit loss rate (annual) | B30: 0.0018
A31: Effective tax rate | B31: 0.3
A32: Dividend payout ratio | B32: 0.75
A33: Avg loans as % of AIEA | B33: 0.77
A35: Cost of equity build
A36: Risk-free rate | B36: 0.043
A37: Equity risk premium | B37: 0.05
A38: Beta selected (peer-triangulated) | B38: 0.75
A39: equals Cost of equity Re (derived) | B39: =Assumptions!$B$36+Assumptions!$B$38*Assumptions!$B$37
A41: Terminal value
A42: Terminal ROE | B42: 0.105
A43: Terminal growth g | B43: 0.035
A45: Peer-gap closure cost-to-income trajectory (UNITE-informed)
A46: Period | B46: Stub | C46: Y1 FY27 | D46: Y2 FY28 | E46: Y3 FY29 | F46: Y4 FY30 | G46: Y5 FY31
A47: Cost-to-income applied | B47: 0.516 | C47: 0.515 | D47: 0.51 | E47: 0.495 | F47: 0.485 | G47: 0.48
A49: Period | B49: Stub | C49: Y1 FY27 | D49: Y2 FY28 | E49: Y3 FY29 | F49: Y4 FY30 | G49: Y5 FY31
...

Sheet P&L Forecast
A1: Muddle Through 5-year P&L — FORMULAS (Step 2 → Step 3 traceable per §11)
A2: All values are formulas. To flex the model: change inputs on the Assumptions sheet (yellow cells).
A4: Line | B4: Stub | C4: Y1 FY27 | D4: Y2 FY28 | E4: Y3 FY29 | F4: Y4 FY30 | G4: Y5 FY31
A5: Industry AIEA growth p.a. (from §3) | B5: =Assumptions!$B$4 | C5: =Assumptions!$B$4 | D5: =Assumptions!$B$4 | E5: =Assumptions!$B$4 | F5: =Assumptions!$B$4 | G5: =Assumptions!$B$4
A6: Less: WBC company offset (5 Forces) | B6: =Assumptions!$B$8 | C6: =Assumptions!$B$8 | D6: =Assumptions!$B$8 | E6: =Assumptions!$B$8 | F6: =Assumptions!$B$8 | G6: =Assumptions!$B$8
A7: equals WBC AIEA growth (derived) | B7: =Assumptions!$B$10 | C7: =Assumptions!$B$10 | D7: =Assumptions!$B$10 | E7: =Assumptions!$B$10 | F7: =Assumptions!$B$10 | G7: =Assumptions!$B$10
A9: Average interest-earning assets (AUDm) | B9: =Assumptions!$B$21*(1+Assumptions!$B$10*0.175) | C9: =Assumptions!$B$21*(1+Assumptions!$B$10*1.18) | D9: =C9*(1+Assumptions!$B$10) | E9: =D9*(1+Assumptions!$B$10) | F9: =E9*(1+Assumptions!$B$10) | G9: =F9*(1+Assumptions!$B$10)
A10: NIM applied (per Assumptions trajectory) | B10: =Assumptions!$B$53 | C10: =Assumptions!$C$53 | D10: =Assumptions!$D$53 | E10: =Assumptions!$E$53 | F10: =Assumptions!$F$53 | G10: =Assumptions!$G$53
A11: Period length (years) | B11: 0.35 | C11: 1 | D11: 1 | E11: 1 | F11: 1 | G11: 1
A12: Net interest income | B12: =B9*B10*B11 | C12: =C9*C10*C11 | D12: =D9*D10*D11 | E12: =E9*E10*E11 | F12: =F9*F10*F11 | G12: =G9*G10*G11
A13: Non-interest income | B13: =Assumptions!$B$15*(0.35/0.5) | C13: =2*Assumptions!$B$15*(1+Assumptions!$B$29) | D13: =C13*(1+Assumptions!$B$29) | E13: =D13*(1+Assumptions!$B$29) | F13: =E13*(1+Assumptions!$B$29) | G13: =F13*(1+Assumptions!$B$29)
A14: Total operating income | B14: =B12+B13 | C14: =C12+C13 | D14: =D12+D13 | E14: =E12+E13 | F14: =F12+F13 | G14: =G12+G13
A16: Cost-to-income applied (from Assumptions) | B16: =Assumptions!$B$47 | C16: =Assumptions!$C$47 | D16: =Assumptions!$D$47 | E16: =Assumptions!$E$47 | F16: =Assumptions!$F$47 | G16: =Assumptions!$G$47
A17: Less: operating expenses | B17: =-B14*B16 | C17: =-C14*C16 | D17: =-D14*D16 | E17: =-E14*E16 | F17: =-F14*F16 | G17: =-G14*G16
A18: Pre-provision profit | B18: =B14+B17 | C18: =C14+C17 | D18: =D14+D17 | E18: =E14+E17 | F18: =F14+F17 | G18: =G14+G17
A20: Memo: average loans (AIEA × loan %) | B20: =B9*Assumptions!$B$33 | C20: =C9*Assumptions!$B$33 | D20: =D9*Assumptions!$B$33 | E20: =E9*Assumptions!$B$33 | F20: =F9*Assumptions!$B$33 | G20: =G9*Assumptions!$B$33
A21: Credit loss rate applied (from Assumptions) | B21: =Assumptions!$B$50 | C21: =Assumptions!$C$50 | D21: =Assumptions!$D$50 | E21: =Assumptions!$E$50 | F21: =Assumptions!$F$50 | G21: =Assumptions!$G$50
A22: Less: credit impairment charges | B22: =-B20*B21*B11 | C22: =-C20*C21*C11 | D22: =-D20*D21*D11 | E22: =-E20*E21*E11 | F22: =-F20*F21*F11 | G22: =-G20*G21*G11
A23: Cash earnings before tax | B23: =B18+B22 | C23: =C18+C22 | D23: =D18+D22 | E23: =E18+E22 | F23: =F18+F22 | G23: =G18+G22
A24: Income tax expense | B24: =-B23*Assumptions!$B$31 | C24: =-C23*Assumptions!$B$31 | D24: =-D23*Assumptions!$B$31 | E24: =-E23*Assumptions!$B$31 | F24: =-F23*Assumptions!$B$31 | G24: =-G23*Assumptions!$B$31
A25: Cash NPAT | B25: =B23+B24 | C25: =C23+C24 | D25: =D23+D24 | E25: =E23+E24 | F25: =F23+F24 | G25: =G23+G24
A27: Cash EPS (AUD) | B27: =B25/Assumptions!$B$26 | C27: =C25/Assumptions!$B$26 | D27: =D25/Assumptions!$B$26 | E27: =E25/Assumptions!$B$26 | F27: =F25/Assumptions!$B$26 | G27: =G25/Assumptions!$B$26

Sheet Per-Share Value
A1: Per-share value — formulas (DDM + Gordon-growth terminal per §15.8)
A2: Discount rate Re flows from Assumptions sheet. Mid-period discounting.
A4: Line | B4: Stub | C4: Y1 FY27 | D4: Y2 FY28 | E4: Y3 FY29 | F4: Y4 FY30 | G4: Y5 FY31
A5: Cash NPAT (from P&L Forecast) | B5: ='P&L Forecast'!B25 | C5: ='P&L Forecast'!C25 | D5: ='P&L Forecast'!D25 | E5: ='P&L Forecast'!E25 | F5: ='P&L Forecast'!F25 | G5: ='P&L Forecast'!G25
A6: × Payout ratio | B6: =Assumptions!$B$32 | C6: =Assumptions!$B$32 | D6: =Assumptions!$B$32 | E6: =Assumptions!$B$32 | F6: =Assumptions!$B$32 | G6: =Assumptions!$B$32
A7: equals Dividends | B7: =B5*B6 | C7: =C5*C6 | D7: =D5*D6 | E7: =E5*E6 | F7: =F5*F6 | G7: =G5*G6
A8: Mid-period time (years from valuation date) | B8: 0.175 | C8: 0.85 | D8: 1.85 | E8: 2.85 | F8: 3.85 | G8: 4.85
A9: Discount factor | B9: =1/(1+Assumptions!$B$39)^B8 | C9: =1/(1+Assumptions!$B$39)^C8 | D9: =1/(1+Assumptions!$B$39)^D8 | E9: =1/(1+Assumptions!$B$39)^E8 | F9: =1/(1+Assumptions!$B$39)^F8 | G9: =1/(1+Assumptions!$B$39)^G8
A10: PV of dividends | B10: =B7*B9 | C10: =C7*C9 | D10: =D7*D9 | E10: =E7*E9 | F10: =F7*F9 | G10: =G7*G9
A12: Sum of PV explicit dividends | C12: =SUM(B10:G10)
A14: Terminal value (per §15.8)
A15: Opening book equity (1H26 close) | C15: =Assumptions!$B$22
A16: Plus: total retained earnings (stub + Y1-Y5) | C16: =SUM(B5:G5)-SUM(B7:G7)
A17: equals Closing book equity at end Y5 | C17: =C15+C16
A18: Terminal ROE | C18: =Assumptions!$B$42
A19: Terminal growth g | C19: =Assumptions!$B$43
A20: Cost of equity Ke | C20: =Assumptions!$B$39
A21: Terminal value (Equity × (ROE-g)/(Ke-g)) | C21: =$C$17*($C$18-$C$19)/($C$20-$C$19)
A22: Discount factor at end Y5 (t=5.35) | C22: =1/(1+Assumptions!$B$39)^5.35
A23: PV of terminal value | C23: =$C$21*$C$22
A25: Equity bridge per §15.7
A26: Sum of PV of explicit dividends | C26: =$C$12
A27: Plus: PV of terminal value | C27: =$C$23
A28: Total value of equity claim | C28: =$C$26+$C$27
A29: Less: AT1 hybrid (§15.7(a)) | C29: =-Assumptions!$B$23
A30: Less: NCI (§15.7(b)) | C30: =-Assumptions!$B$24
A31: Less: treasury shares (§15.7(g)) | C31: =-Assumptions!$B$25
A32: Ordinary equity value | C32: =$C$28-Assumptions!$B$23-Assumptions!$B$24-Assumptions!$B$25
A33: ÷ Shares outstanding (m) | C33: =Assumptions!$B$26
A34: VALUE PER SHARE | C34: =$C$32/Assumptions!$B$26
