Workbook

Sheet Cover
B1: Dyno Nobel Limited (DNL.AU) — Muddle Through valuation (v2)
B3: Scenario: | C3: Muddle Through (interior, most-likely)
B4: Valuation date: | C4: 25 May 2026
B5: Anchor date (financials): | C5: 31 March 2026 (H1 FY26)
B6: Reporting currency: | C6: AUD millions unless noted
B7: Fiscal year-end: | C7: 30 September
B8: Workbook version: | C8: v2 (applies full methodology per design/methodology/equity_bridge_and_valuation_mechanics.md)
B10: What's new vs v1:
B11: Base re-anchored | C11: FY26 continuing-ops only (not TTM Mar 2026 which included Phosphate Hill)
B12: Revenue growth from chain | C12: Scenario macro -> industry archetype -> DNL geographic mix (~5.5% nominal vs prior 2.0%)
B13: Margin glide path | C13: Base 12.9% glides to 14.9% by FY28 (transformation programme), 15.1% steady state
B14: Period A walk | C14: Net debt walked from 31 Mar 2026 anchor to 25 May 2026 valuation date
B15: Period B stub | C15: Stub period (May-Sep 2026) shown as own DCF line
B16: Mid-period discounting | C16: Cash flows treated as mid-period; terminal at end of Year 5
B17: Statutory + ex-IMI DCFs | C17: Both bases shown; user picks central case
B18: IMI Register | C18: Each IMI with frequency context + default lean
B19: Equity Bridge | C19: Structured walk: EV -> reported net debt -> period A walk -> declared dividend -> ARO gap -> contingent receivable -> equity -> per share
B21: Tabs:
B22: Assumptions | C22: Single source of truth; all inputs blue, formulas black
B23: Macro & Growth Build | C23: Scenario macro -> industry archetype translation -> DNL position -> growth path
B24: P&L Summary | C24: Historicals + 5-year forecast (continuing operations)
B25: Balance Sheet | C25: At 31 Mar 2026; reported + normalised steady-state anchors
B26: WACC Build | C26: Component build pulling from Assumptions (unchanged from v1)
B27: IMI Register | C27: Each IMI item with context + default lean; user override toggle
B28: DCF Worksheet | C28: Stub + 5 explicit years + Gordon-growth terminal; statutory and ex-IMI bases
B29: Equity Bridge | C29: Full structured walk from EV to per share
B31: Sources:
B32: H1 FY26 announcement | C32: 2026 Half Year Results Announcement (11 May 2026); ASX release
B33: H1 FY26 investor pres | C33: 2026 Half Year Results Investor Presentation
B34: Reported financials | C34: data/financials/dnl.yaml (EODHD, 22 May 2026) + H1 H1 announcement updates
B35: Methodology | C35: design/methodology/equity_bridge_and_valuation_mechanics.md (v0.1)
B36: Architecture spec | C36: design/architecture.md v0.3
B38: Market reference: | C38: Share price AUD 3.61, consensus target AUD 3.61 (21 May 2026); EV AUD 7,682m
B40: Colour key:
B41: Blue text | C41: Hardcoded input — override here to flow through the model
B42: Black text | C42: Formula / calculation
B43: Green text | C43: Cross-sheet link
B44: Yellow background | C44: Key assumption — flagged for attention

Sheet Assumptions
A1: Parameter | B1: Value | C1: Units | D1: Source / rationale
A2: DATES (per methodology section 7)
A3: Valuation date | B3: 25-May-2026 | D3: Today; explicit per methodology section 7.
A4: Anchor date (financials) | B4: 31-Mar-2026 | D4: H1 FY26 reporting date. All net-debt + share-count figures pair to this date.
A5: Year 1 start (next FY) | B5: 1-Oct-2026 | D5: Start of FY27. Stub period runs valuation date to here.
A6: Stub period (years) | B6: 0.351 | C6: yrs | D6: 128 days / 365. Used for stub-period FCF and mid-period discount factors.
A8: BASE YEAR (FY26 continuing operations — estimate)
A9: Base year revenue (FY26) | B9: 3400 | C9: AUD m | D9: FY26 continuing-ops Explosives revenue. H1 actual AUD 1,610m; H2 implied ~AUD 1,790m given FY26 EBIT guidance midpoint AUD 480m at ~14% margin. Excludes discontinued Phosphate Hill.
A10: Base year EBIT margin (Group, FY26) | B10: 0.129 | C10: % | D10: FY26 Group EBIT = Explosives EBIT AUD 480m (midpoint guidance) - Corporate costs AUD 40m = AUD 440m. AUD 440m / AUD 3,400m = 12.9%.
A11: Steady-state capex/revenue (long run) | B11: 0.07 | C11: % | D11: Pre-demerger normalised. FY26 transitionally elevated.
A12: FY26-27 capex/revenue (transition) | B12: 0.08 | C12: % | D12: FY26 guidance AUD 250-300m on AUD 3,400m revenue = ~8%. Tapers to steady state by FY30.
A13: D&A / revenue | B13: 0.073 | C13: % | D13: Approximate steady-state ratio.
A14: Tax rate (effective, FY26 guidance) | B14: 0.225 | C14: % | D14: FY26 effective tax rate ex IMIs guided 20-25%. Lower than 30% statutory due to franking, R&D, foreign tax credits.
A15: Working capital change | B15: 0 | C15: AUD m / yr | D15: Smoke-test simplification: neutral. Step 6 production translator will derive from working_capital_days x revenue growth.
A17: SCENARIO MACRO BASELINE (Muddle Through)
A18: DM real GDP growth | B18: 0.02 | C18: % | D18: Aus 1.8-2.2%, US 1.8-2.2%; central estimate 2.0%.
A19: DM inflation (normalising) | B19: 0.025 | C19: % | D19: Gradually normalising from current ~3% toward target 2%; central 2.5%.
A20: Global mining real growth | B20: 0.025 | C20: % | D20: Tracks real GDP with EM mining-volume tilt; +50bps from depletion / ore-grade decline.
A21: Gas price growth (input cost proxy) | B21: 0.02 | C21: % | D21: No commodity boom in Muddle Through; tracks long-run inflation.
A22: DM nominal GDP (derived) | B22: =(1+B18)*(1+B19)-1 -> 0.0455 | C22: % | D22: (1+real)*(1+inflation)-1
A24: INDUSTRY ARCHETYPE TRANSLATION (industrial explosives)
A25: Volume formula coefficient (a) | B25: 1.15 | D25: volume_growth = a * mining_real_growth + b
A26: Volume formula constant (b) | B26: 0.004 | D26: Pickup from ore-grade decline / waste tonnage growth.
A27: Industry volume growth (derived) | B27: =B25*B20+B26 -> 0.03275 | C27: % | D27: a * mining_real_growth + b
A28: Pricing weight on inflation | B28: 0.7 | D28: 70% of price tracks DM inflation (broad cost base).
A29: Pricing weight on gas | B29: 0.3 | D29: 30% of price tracks gas input cost (ammonia/AN feedstock).
A30: Productivity sharing (bps) | B30: 0.005 | C30: % | D30: 50bps net per year — long-run productivity uplift shared with customers.
A31: Industry pricing growth (derived) | B31: =B28*B19+B29*B21+B30 -> 0.0285 | C31: % | D31: pricing_weight_inflation * DM_inflation + pricing_weight_gas * gas_price_growth + productivity_sharing
A32: Industry nominal growth (derived) | B32: =(1+B27)*(1+B31)-1 -> 0.062183375 | C32: % | D32: (1 + vol) * (1 + price) - 1
A34: DNL COMPANY-POSITION OFFSETS
A35: DM weighting (Aus + US) | B35: 0.9 | C35: % | D35: DNL geographic mix: ~55% US + ~35% Australia = 90% mature markets.
A36: EM weighting (DNEL: LATAM/EMEA) | B36: 0.1 | C36: % | D36: ~10% EMEA/LATAM via DNEL — growing but small base.
A37: EM growth premium vs DM (multiplier) | B37: 1.3 | D37: EM mining-services markets growing ~30% faster than DM in nominal terms.
A38: Geographic-mix multiplier (derived) | B38: =B35+B36*B37 -> 1.03 | D38: DM weight + EM weight * EM premium. Applies to industry growth.
A39: DNL company offset (bps) | B39: -0.005 | C39: % | D39: Mature-market drag net of DNEL pipeline. -50bps central case.
A40: DNL nominal revenue growth (derived) | B40: =B32*B38+B39 -> 0.059048876 | C40: % | D40: industry_nominal * geo_mix_multiplier + company_offset
A42: MARGIN GLIDE PATH (transformation overlay)
A43: FY27 margin delta (Year 1) | B43: 0.01 | C43: pp | D43: +100bps from transformation residual. Reaches ~13.9% Group EBIT margin.
A44: FY28 margin delta (Year 2 cum) | B44: 0.02 | C44: pp | D44: +200bps cumulative. Aligns to AUD 600m EBIT ambition (Explosives) less corporate.
A45: FY29 margin delta (Year 3 cum) | B45: 0.022 | C45: pp | D45: +220bps cumulative. Final transformation tail.
...

Sheet P&L Summary
A1: DNL P&L summary — historicals + Muddle Through 5-year forecast (continuing ops, AUD m)
A3: Period | B3: FY2024 | C3: FY2025 | D3: H1 FY26 (act) | E3: FY26 (base est) | G3: Y1 (FY27e) | H3: Y2 (FY28e) | I3: Y3 (FY29e) | J3: Y4 (FY30e) | K3: Y5 (FY31e) | L3: Notes
A5: REVENUE (continuing operations: Explosives only)
A6: Revenue | B6: 3700 | C6: 3220 | D6: 1609.8 | E6: =Assumptions!$B$9 -> 3400 | G6: =E6*(1+Assumptions!$B$40) -> 3600.7662 | H6: =G6*(1+Assumptions!$B$40) -> 3813.3874 | I6: =H6*(1+Assumptions!$B$40) -> 4038.5636 | J6: =I6*(1+Assumptions!$B$40) -> 4277.0363 | K6: =J6*(1+Assumptions!$B$40) -> 4529.5904 | L6: FY24/25 historical group revenue (combined entity). FY26 = continuing-ops Explosives only. Forecast grows at DNL Muddle Through chain-derived rate.
A7: y/y growth | C7: =C6/B6-1 -> -0.12972973 | E7: =E6/C6-1 -> 0.055900621 | G7: =G6/E6-1 -> 0.059048876 | H7: =H6/G6-1 -> 0.059048876 | I7: =I6/H6-1 -> 0.059048876 | J7: =J6/I6-1 -> 0.059048876 | K7: =K6/J6-1 -> 0.059048876 | L7: FY26 vs FY25 grows in continuing-ops terms (after Phosphate Hill exit) — direct compare misleading.
A9: EBIT (Group; ex IMIs)
A10: EBIT margin (applied) | D10: 0.139 | E10: =Assumptions!$B$10 -> 0.129 | G10: =Assumptions!$B$10+Assumptions!$B$43 -> 0.139 | H10: =Assumptions!$B$10+Assumptions!$B$44 -> 0.149 | I10: =Assumptions!$B$10+Assumptions!$B$45 -> 0.151 | J10: =Assumptions!$B$10+Assumptions!$B$46 -> 0.151 | K10: =Assumptions!$B$10+Assumptions!$B$47 -> 0.151 | L10: FY26 base + transformation glide path (margin delta per year, cumulative).
A11: EBIT | D11: =D6*D10 -> 223.7622 | E11: =E6*E10 -> 438.6 | G11: =G6*G10 -> 500.5065 | H11: =H6*H10 -> 568.19472 | I11: =I6*I10 -> 609.82311 | J11: =J6*J10 -> 645.83247 | K11: =K6*K10 -> 683.96816 | L11: Revenue x margin. FY26 reconciles to AUD 440m (= AUD 480m Explosives midpoint - AUD 40m Corporate).
A13: BELOW EBIT
A14: Tax on EBIT (effective rate) | G14: =-G11*Assumptions!$B$14 -> -112.61396 | H14: =-H11*Assumptions!$B$14 -> -127.84381 | I14: =-I11*Assumptions!$B$14 -> -137.2102 | J14: =-J11*Assumptions!$B$14 -> -145.31231 | K14: =-K11*Assumptions!$B$14 -> -153.89284 | L14: Effective rate per FY26 guidance midpoint (22.5%); franking + R&D + foreign tax credits.
A15: NOPAT (Group) | G15: =G11+G14 -> 387.89254 | H15: =H11+H14 -> 440.35091 | I15: =I11+I14 -> 472.61291 | J15: =J11+J14 -> 500.52017 | K15: =K11+K14 -> 530.07532

Sheet Balance Sheet
A1: DNL balance sheet summary at 31 March 2026 (H1 FY26 anchor; AUD m)
A3: Line | B3: AUD m | C3: Notes
A4: ASSETS
A5: Total assets (per H1 disclosure) | B5: 5863.3 | C5: Down from AUD 6,199m at 30 Sep 2025 (Phosphate Hill reclass + FX).
A7: LIABILITIES
A8: Environmental & restructure liabilities | B8: 249.3 | C8: Down AUD 125m H/H: AUD 82m of Phosphate Hill ARO reclassified to Held for Sale; AUD 33m payments. Net remaining ARO obligation already substantially provided.
A9: Lease liabilities | B9: 194.3 | C9: AASB 16 leases.
A10: Net debt (reported, H1 anchor) | B10: 1260.8 | C10: Interest-bearing liabilities + capital leases - cash - hedging derivatives. Up AUD 80m H/H driven by buyback AUD 128m + dividends paid AUD 170m, offset by Gibson Island sale proceeds AUD 198m.
A11: Net liabilities classified as held for sale | B11: 111.5 | C11: Phosphate Hill (sale binding agreement signed March 2026).
A12: Total liabilities | B12: 1815.9
A13: Net assets / Total equity | B13: 4047.4 | C13: Down AUD 385m H/H — Phosphate Hill IMI write-down + capital returns.
A15: CREDIT METRICS
A16: Net debt / EBITDA (TTM) | B16: 1.3 | C16: Per H1 disclosure. Well within 2.0x policy.
A17: Interest cover | B17: 12.5 | C17: Per H1 disclosure. Above 6.0x target.
A18: Credit rating (S&P) | B18: BBB stable | C18: Per H1 disclosure.
A19: Credit rating (Moody's) | B19: Baa2 stable | C19: Per H1 disclosure.
A21: NET DEBT EVOLUTION (per methodology section 7)
A22: Net debt at 31 Mar 2026 (anchor) | B22: =B10 -> 1260.8 | C22: Same as row 10; restated as starting point for Period A walk.
A23: Period A walk forward (-> 25 May 2026) | B23: ='Equity Bridge'!B10 -> 19.876712 | C23: From dedicated Period A calc; see Equity Bridge tab.
A24: Net debt at 25 May 2026 (valuation date) | B24: =B22+B23 -> 1280.6767 | C24: Reported net debt walked to valuation date.

Sheet WACC Build
A1: DNL WACC component build-up (Muddle Through)
B3: Value | C3: Units | D3: Source / formula
A4: COST OF EQUITY (CAPM)
A5: Risk-free rate (Rf) | B5: =Assumptions!$B$50 -> 0.043 | C5: % | D5: 10Y AUD govt bond.
A6: Equity risk premium (ERP) | B6: =Assumptions!$B$51 -> 0.05 | C6: % | D6: Mature-Aus ERP.
A7: Beta | B7: =Assumptions!$B$52 -> 1.15 | D7: Pre-demerger IPL 1.05-1.10; pure-play uplift.
A8: Cost of equity (Re) | B8: =B5+B7*B6 -> 0.1005 | C8: % | D8: Re = Rf + Beta x ERP.
A10: COST OF DEBT (AFTER-TAX)
A11: Cost of debt, pre-tax (Rd) | B11: =Assumptions!$B$53 -> 0.06 | C11: % | D11: BBB spread ~170bps over 10Y AUD sovereign.
A12: Tax rate | B12: =Assumptions!$B$14 -> 0.225 | C12: % | D12: Effective rate per FY26 guidance midpoint.
A13: Cost of debt, after-tax | B13: =B11*(1-B12) -> 0.0465 | C13: % | D13: Rd_after_tax = Rd_pretax x (1 - tax).
A15: CAPITAL-STRUCTURE WEIGHTS (market value)
A16: Equity market value (E) | B16: =Assumptions!$B$54 -> 6390 | C16: AUD m | D16: Per H1 disclosure: AUD 6,390m at 21 May 2026.
A17: Debt market value (D) | B17: =Assumptions!$B$55 -> 1260.8 | C17: AUD m | D17: Reported net debt 31 Mar 2026.
A18: Enterprise value (V = E + D) | B18: =B16+B17 -> 7650.8 | C18: AUD m
A19: Equity weight (E/V) | B19: =B16/B18 -> 0.83520678 | C19: %
A20: Debt weight (D/V) | B20: =B17/B18 -> 0.16479322 | C20: %
A22: WACC
A23: Baseline WACC | B23: =B19*B8+B20*B13 -> 0.091601166 | C23: % | D23: WACC = (E/V) x Re + (D/V) x Rd_after_tax.

Sheet IMI Register
A1: DNL IMI Register — H1 FY26
A3: IMI item | B3: After tax (AUD m) | C3: Gross (AUD m) | D3: P&L line | E3: Frequency context | F3: Default lean | G3: Applied
A4: Phosphate Hill impairment + site exit costs | B4: 125.9 | C4: 179.6 | D4: above_ebit | E4: First occurrence; tied to specific divestment (Phosphate Hill sale binding agreement signed March 2026). | F4: accept_as_one_off | G4: strip
A5: IPF Distribution settlement / Gibson Island land | B5: 11.2 | C5: 11.2 | D5: below_ebit | E5: Tied to FY25 divestments; final purchase-price adjustments. Will not recur. | F5: accept_as_one_off | G5: strip
A6: Business transformation costs | B6: 3.9 | C6: 5.6 | D6: above_ebit | E6: Appeared in FY24, FY25, FY26 H1 (3 consecutive years). Fertilisers separation now complete (March 2026); expected to roll off over 12-18 months. | F6: partial_recur (borderline) | G6: strip
A7: Total IMIs (H1 FY26) | B7: =SUM(B4:B6) -> 141 | C7: =SUM(C4:C6) -> 196.4
A9: VALUATION IMPACT (continuing forward run-rate)
A10: Forward annual transformation IMI run-rate (after tax) | B10: 8 | E10: If 'keep' transformation costs in underlying: AUD ~8m/yr after tax for next 12-18 months, declining to nil.
A11: Switch: apply transformation costs to forecast? | E11: Default = NO (strip per Tara's view: fertilisers separation done, transformation winding down). Toggle to YES to apply costs. | G11: NO

Sheet DCF Worksheet
A1: DNL DCF — Muddle Through (stub + 5-yr explicit + Gordon-growth terminal)
A3: Line | B3: Stub (May-Sep 26) | C3: Y1 (FY27) | D3: Y2 (FY28) | E3: Y3 (FY29) | F3: Y4 (FY30) | G3: Y5 (FY31) | H3: Terminal | I3: Notes
A5: INPUTS (linked from P&L Summary; stub pro-rated)
A6: Revenue (AUD m) | B6: =Assumptions!$B$6*Assumptions!$B$9 -> 1193.4 | C6: ='P&L Summary'!G6 -> 3600.7662 | D6: ='P&L Summary'!H6 -> 3813.3874 | E6: ='P&L Summary'!I6 -> 4038.5636 | F6: ='P&L Summary'!J6 -> 4277.0363 | G6: ='P&L Summary'!K6 -> 4529.5904 | I6: Stub = stub_years x FY26 base. Y1-Y5 linked from P&L (already grown by chain-derived rate).
A7: EBIT margin | B7: =Assumptions!$B$10 -> 0.129 | C7: ='P&L Summary'!G10 -> 0.139 | D7: ='P&L Summary'!H10 -> 0.149 | E7: ='P&L Summary'!I10 -> 0.151 | F7: ='P&L Summary'!J10 -> 0.151 | G7: ='P&L Summary'!K10 -> 0.151
A8: EBIT | B8: =B6*B7 -> 153.9486 | C8: =C6*C7 -> 500.5065 | D8: =D6*D7 -> 568.19472 | E8: =E6*E7 -> 609.82311 | F8: =F6*F7 -> 645.83247 | G8: =G6*G7 -> 683.96816
A9: less: transformation IMI costs (if applied) | B9: =IF('IMI Register'!G11="YES",IF("B"="B",-Assumptions!$B$6*12,IF("B"="C",-12,IF("B"="D",-6,0))),0) -> 0 | C9: =IF('IMI Register'!G11="YES",IF("C"="B",-Assumptions!$B$6*12,IF("C"="C",-12,IF("C"="D",-6,0))),0) -> 0 | D9: =IF('IMI Register'!G11="YES",IF("D"="B",-Assumptions!$B$6*12,IF("D"="C",-12,IF("D"="D",-6,0))),0) -> 0 | E9: =IF('IMI Register'!G11="YES",IF("E"="B",-Assumptions!$B$6*12,IF("E"="C",-12,IF("E"="D",-6,0))),0) -> 0 | F9: =IF('IMI Register'!G11="YES",IF("F"="B",-Assumptions!$B$6*12,IF("F"="C",-12,IF("F"="D",-6,0))),0) -> 0 | G9: =IF('IMI Register'!G11="YES",IF("G"="B",-Assumptions!$B$6*12,IF("G"="C",-12,IF("G"="D",-6,0))),0) -> 0
A10: EBIT (applied basis) | B10: =B8+B9 -> 153.9486 | C10: =C8+C9 -> 500.5065 | D10: =D8+D9 -> 568.19472 | E10: =E8+E9 -> 609.82311 | F10: =F8+F9 -> 645.83247 | G10: =G8+G9 -> 683.96816
A12: FCF BRIDGE
A13: Less: tax on EBIT | B13: =-B10*Assumptions!$B$14 -> -34.638435 | C13: =-C10*Assumptions!$B$14 -> -112.61396 | D13: =-D10*Assumptions!$B$14 -> -127.84381 | E13: =-E10*Assumptions!$B$14 -> -137.2102 | F13: =-F10*Assumptions!$B$14 -> -145.31231 | G13: =-G10*Assumptions!$B$14 -> -153.89284
A14: NOPAT | B14: =B10+B13 -> 119.31016 | C14: =C10+C13 -> 387.89254 | D14: =D10+D13 -> 440.35091 | E14: =E10+E13 -> 472.61291 | F14: =F10+F13 -> 500.52017 | G14: =G10+G13 -> 530.07532
A15: Plus: D&A | B15: =B6*Assumptions!$B$13 -> 87.1182 | C15: =C6*Assumptions!$B$13 -> 262.85593 | D15: =D6*Assumptions!$B$13 -> 278.37728 | E15: =E6*Assumptions!$B$13 -> 294.81514 | F15: =F6*Assumptions!$B$13 -> 312.22365 | G15: =G6*Assumptions!$B$13 -> 330.6601
A16: Less: capex | B16: =-B6*Assumptions!$B$12 -> -95.472 | C16: =-C6*Assumptions!$B$12 -> -288.06129 | D16: =-D6*Assumptions!$B$12 -> -305.07099 | E16: =-E6*Assumptions!$B$11 -> -282.69945 | F16: =-F6*Assumptions!$B$11 -> -299.39254 | G16: =-G6*Assumptions!$B$11 -> -317.07133
A17: Less: change in WC | B17: =-Assumptions!$B$15 -> 0 | C17: =-Assumptions!$B$15 -> 0 | D17: =-Assumptions!$B$15 -> 0 | E17: =-Assumptions!$B$15 -> 0 | F17: =-Assumptions!$B$15 -> 0 | G17: =-Assumptions!$B$15 -> 0
A18: Unlevered FCFF | B18: =SUM(B14:B17) -> 110.95637 | C18: =SUM(C14:C17) -> 362.68717 | D18: =SUM(D14:D17) -> 413.6572 | E18: =SUM(E14:E17) -> 484.7286 | F18: =SUM(F14:F17) -> 513.35128 | G18: =SUM(G14:G17) -> 543.66409
A20: DISCOUNTING (mid-period, from valuation date)
A21: WACC | B21: ='WACC Build'!$B$23 -> 0.091601166 | C21: ='WACC Build'!$B$23 -> 0.091601166 | D21: ='WACC Build'!$B$23 -> 0.091601166 | E21: ='WACC Build'!$B$23 -> 0.091601166 | F21: ='WACC Build'!$B$23 -> 0.091601166 | G21: ='WACC Build'!$B$23 -> 0.091601166
A22: Time to mid-cash-flow (yrs from val date) | B22: =Assumptions!$B$6/2 -> 0.1755 | C22: =Assumptions!$B$6+1-0.5 -> 0.851 | D22: =Assumptions!$B$6+2-0.5 -> 1.851 | E22: =Assumptions!$B$6+3-0.5 -> 2.851 | F22: =Assumptions!$B$6+4-0.5 -> 3.851 | G22: =Assumptions!$B$6+5-0.5 -> 4.851
A23: Discount factor | B23: =1/(1+B21)^B22 -> 0.9847359 | C23: =1/(1+C21)^C22 -> 0.92812729 | D23: =1/(1+D21)^D22 -> 0.85024396 | E23: =1/(1+E21)^E22 -> 0.77889616 | F23: =1/(1+F21)^F22 -> 0.71353548 | G23: =1/(1+G21)^G22 -> 0.6536595
A24: PV of FCFF | B24: =B18*B23 -> 109.26272 | C24: =C18*C23 -> 336.61986 | D24: =D18*D23 -> 351.70953 | E24: =E18*E23 -> 377.55324 | F24: =F18*F23 -> 366.29435 | G24: =G18*G23 -> 355.3712
A26: TERMINAL VALUE (Gordon growth)
A27: Terminal growth | H27: =Assumptions!$B$58 -> 0.025
A28: Terminal-year FCF (Y5 FCF x (1+g)) | H28: =G18*(1+H27) -> 557.2557
A29: Terminal value (TFCF / (WACC-g)) | H29: =H28/(G21-H27) -> 8367.0562
A30: Time to end Y5 (yrs from val date) | H30: =Assumptions!$B$6+Assumptions!$B$59 -> 5.351
A31: Discount factor at end Y5 | H31: =1/(1+G21)^H30 -> 0.62563291
A32: PV of terminal value | H32: =H29*H31 -> 5234.7057
A34: ENTERPRISE VALUE
A35: Sum PV explicit FCFF (stub + Y1-Y5) | H35: =SUM(B24:G24) -> 1896.8109
A36: Plus: PV terminal | H36: =H32 -> 5234.7057
A37: Enterprise value (EV) | H37: =H35+H36 -> 7131.5166
A38: Terminal share of EV (diagnostic) | H38: =H36/H37 -> 0.73402419

Sheet Equity Bridge
A1: DNL Equity Bridge — EV to value per share
A3: Line | B3: Component | C3: Running net debt | D3: Notes
A5: PERIOD A WALK (anchor -> valuation date)
A6: Net debt at 31 Mar 2026 (anchor) | B6: =Assumptions!$B$55 -> 1260.8 | D6: From Assumptions; H1 reported net debt.
A7: less: operating cash flow in Period A | B7: =-Assumptions!$B$67*Assumptions!$B$66 -> -43.69863 | D7: Operating cash inflow reduces net debt. Run rate x Period A in years.
A8: plus: capex paid in Period A | B8: =Assumptions!$B$68*Assumptions!$B$66 -> 38.575342 | D8: Capex increases net debt.
A9: plus: buyback completed in Period A | B9: =Assumptions!$B$69 -> 25 | D9: Buyback cash outflow; value-neutral per methodology section 5.2 (so doesn't affect per-share), but increases net debt.
A10: Net debt walk subtotal | B10: =SUM(B7:B9) -> 19.876712
A11: Net debt at 25 May 2026 (valuation date) | C11: =B6+B10 -> 1280.6767
A13: EQUITY-BRIDGE ADJUSTMENTS (per methodology section 4)
A14: Plus: declared unpaid dividend (interim, 11 May 2026) | B14: =Assumptions!$B$72 -> 81.4 | D14: Declared post-anchor; not in net debt under DNL's narrow definition. AASB liability; will be paid July 2026.
A15: Plus: Phosphate Hill ARO net gap | B15: =Assumptions!$B$75 -> 44 | D15: Commitment AUD 126m less existing provision AUD 82m. Restructure-consistency rule: we assume the benefit (no Phosphate Hill loss in forecast) so must include the cost.
A16: Plus: Phosphate Hill inventory commitment | B16: =Assumptions!$B$76 -> 80 | D16: Inventory to be transferred at completion. Not yet provided.
A17: Plus: restructure execution cash cost | B17: =Assumptions!$B$77 -> 12 | D17: Remaining transformation cash costs. Required by methodology section 4.4.
A18: Less: Perdaman contingent receivable (prob-wtd) | B18: =-Assumptions!$B$80 -> -72.5 | D18: Constrained under AASB 15 (not on BS). Probability-weighted face value.
A19: Total equity-bridge adjustments | B19: =SUM(B14:B18) -> 144.9
A21: VALUE PER SHARE
A22: Enterprise value (from DCF) | C22: ='DCF Worksheet'!H37 -> 7131.5166
A23: Less: net debt at valuation date | C23: =-C11 -> -1280.6767
A24: Less: equity-bridge adjustments (net) | C24: =-B19 -> -144.9
A25: Equity value | C25: =C22+C23+C24 -> 5705.9399
A26: Divided by shares outstanding (period-end H1) | C26: =Assumptions!$B$62 -> 1770
A27: VALUE PER SHARE | C27: =C25/C26 -> 3.2236948
A29: MARKET CHECK
A30: Market reference per share | C30: =Assumptions!$B$83 -> 3.61
A31: Discount / (premium) vs market | C31: =C27/C30-1 -> -0.10700974 | D31: Negative = our valuation below market; positive = above. Muddle Through is the more-sceptical-than-market case by design.
