Workbook

Sheet Cover
B1: Dyno Nobel Limited (DNL.AU) — Muddle Through valuation v4 (29 May 2026)
B3: Scenario: | C3: Muddle Through (interior, most-likely)
B4: Valuation date: | C4: 25 May 2026
B5: Anchor date (financials): | C5: 31 March 2026 (H1 FY26)
B6: Headline per share: | C6: AUD 3.57 (vs market AUD 3.61, -1.2%)
B8: What changed in v4 (review feedback):
B9: Q1 — Base EBIT | C9: Corrected to AUD 480m (was AUD 440m). Slide 27 + 28 confirm guidance is Total Dyno Nobel underlying, with corporate already deducted at segment level. Base margin 14.1% (was 12.9%).
B10: Q2/Q3 — Margin glide reconciled | C10: Y1 transformation delta lowered to +60bps; FY27 lands at ~AUD 530m (mid-upper exit run-rate AUD 495-525m). FY28 +180bps reaches AUD 600m ambition.
B11: Q6 — OCF run rate | C11: Period A walk-forward uses AUD 500m underlying (H1 AUD 145m grossed up for one-off TWC unwind), not AUD 290m simple-double.
B12: Q7 — Fertilisers separation cash flows | C12: Slide 29 list complete: added IPF Distribution deferred +AUD 125m (prob-weighted), Geelong remediation -AUD 35m, Gibson Island remediation -AUD 97m, transaction costs -AUD 11m, Phosphate Hill contingent +AUD 100m (prob-weighted at 30%).
B13: Q8 — Buyback inconsistency | C13: Removed Period A buyback adjustment. Per methodology section 5.2 (on-market buyback at fair value is value-neutral). Share count and net debt both at 31 March 2026 anchor.
B14: WACC (i) — Hamada | C14: Confirmed: re-lever using Hamada with marginal-rate tax shield (30%).
B15: WACC (ii) — World index | C15: Beta convention now AUD-MSCI World as primary for companies with >30% non-Australian revenue. DNL beta: 0.95 (vs 1.15 ASX200 in v3).
B16: WACC (iii) — Lower WACC | C16: Applied WACC drops 9.16% -> 8.25%. Dominant mover for the change in per-share value.
B17: Tax — Effective glides to blended statutory | C17: Effective 22.5% (Y1) -> blended statutory 27.5% (Y5/terminal), linear glide. Blended statutory = sum of jurisdictional weights x statutory rates. Captures structural US-mix advantage (persistent ~2.5pp gap to AU statutory).
B19: New tabs in v4:
B20: Tax Bridge | C20: Jurisdictional weights table + tax glide path.
B21: Sources | C21: Audit-trail tab citing specific H1 financial report pages and slides.
B23: Methodology references:
B24: Equity bridge & valuation mechanics | C24: design/methodology/equity_bridge_and_valuation_mechanics.md (sections 3.1-3.5, 4-7)
B25: Single WACC discipline | C25: section 3.5
B26: Structural headwind overlay | C26: section 3.2.1 (gas-contract roll-off remains in v4)
B27: Tax discipline (new, pending §3.6) | C27: Effective glides to blended statutory by terminal year. Sources: jurisdictional revenue mix, statutory rates by jurisdiction.
B29: Colour key:
B30: Blue text | C30: Hardcoded input — override to flow through the model
B31: Black text | C31: Formula / calculation
B32: Green text | C32: Cross-sheet link
B33: Yellow background | C33: Key assumption — flagged for attention

Sheet Assumptions
A1: Parameter | B1: Value | C1: Units | D1: Source / rationale
A2: DATES (per methodology section 7)
A3: Valuation date | B3: 25-May-2026 | D3: Today.
A4: Anchor date (financials) | B4: 31-Mar-2026 | D4: H1 FY26.
A5: Year 1 start (next FY) | B5: 1-Oct-2026 | D5: FY27 start.
A6: Stub period (years) | B6: 0.351 | C6: yrs | D6: 128 days / 365.
A8: BASE YEAR (FY26 — corrected per Q1 review)
A9: Base year revenue (FY26) | B9: 3400 | C9: AUD m | D9: FY26 continuing-ops Explosives revenue (excludes discontinued Phosphate Hill). Implied from H1 actual AUD 1,610m + H2 ~AUD 1,790m given guidance midpoint EBIT AUD 480m at margin ~14.1%.
A10: Base year EBIT margin (Group, FY26) | B10: 0.141 | C10: % | D10: AUD 480m guidance midpoint / AUD 3,400m revenue. Q1 correction: corporate ALREADY DEDUCTED in segment guidance per slides 27-28 of H1 investor presentation. Was 12.9% in v3 (-12% double-counting error).
A11: Steady-state capex/revenue (long run) | B11: 0.07 | C11: % | D11: Pre-demerger normalised pattern.
A12: FY26-27 capex/revenue (transition) | B12: 0.08 | C12: % | D12: FY26 guidance AUD 250-300m on AUD 3,400m revenue = ~8%.
A13: D&A / revenue | B13: 0.073 | C13: % | D13: Steady-state approx; FY25 actual 7.66%.
A14: Working capital change | B14: 0 | C14: AUD m / yr | D14: Smoke-test simplification: neutral.
A16: SCENARIO MACRO BASELINE (Muddle Through)
A17: DM real GDP growth | B17: 0.02 | C17: % | D17: Aus 1.8-2.2%, US 1.8-2.2%; central 2.0%.
A18: DM inflation (normalising) | B18: 0.025 | C18: % | D18: Gradually normalising; central 2.5%.
A19: Global mining real growth | B19: 0.025 | C19: % | D19: Tracks real GDP with EM mining tilt; +50bps from depletion / ore-grade decline.
A20: Gas price growth (input cost proxy) | B20: 0.02 | C20: % | D20: No commodity boom in Muddle Through; tracks long-run inflation.
A22: INDUSTRY ARCHETYPE TRANSLATION (industrial explosives)
A23: Volume formula coefficient (a) | B23: 1.15 | D23: volume_growth = a x mining_real_growth + b
A24: Volume formula constant (b) | B24: 0.004 | D24: Pickup from ore-grade decline / waste tonnage.
A25: Industry volume growth (derived) | B25: =B23*B19+B24 -> 0.03275 | C25: % | D25: a x mining_real_growth + b
A26: Pricing weight on inflation | B26: 0.7 | D26: 70% of price tracks DM inflation.
A27: Pricing weight on gas | B27: 0.3 | D27: 30% of price tracks gas input cost.
A28: Productivity sharing (bps) | B28: 0.005 | C28: % | D28: 50bps net productivity uplift per year.
A29: Industry pricing growth (derived) | B29: =B26*B18+B27*B20+B28 -> 0.0285 | C29: % | D29: pricing_weight_inflation x DM_inflation + pricing_weight_gas x gas_growth + productivity_sharing
A30: Industry nominal growth (derived) | B30: =(1+B25)*(1+B29)-1 -> 0.062183375 | C30: % | D30: (1+vol) x (1+price) - 1
A32: DNL COMPANY-POSITION OFFSETS
A33: DM weighting (Aus + US) | B33: 0.9 | C33: % | D33: DNL geographic mix: ~55% US + ~35% Australia = 90% mature markets.
A34: EM weighting (DNEL: LATAM / EMEA) | B34: 0.1 | C34: % | D34: ~10% EMEA/LATAM.
A35: EM growth premium vs DM (multiplier) | B35: 1.3 | D35: EM mining-services markets growing ~30% faster than DM in nominal terms.
A36: Geographic-mix multiplier (derived) | B36: =B33+B34*B35 -> 1.03 | D36: DM weight + EM weight x EM premium.
A37: DNL company offset (bps) | B37: -0.005 | C37: % | D37: Mature-market drag net of DNEL pipeline. -50bps central case.
A38: DNL nominal revenue growth (Muddle Through) | B38: =B30*B36+B37 -> 0.059048876 | C38: % | D38: industry_nominal x geo_mix_multiplier + company_offset. Per methodology section 2.
A40: MARGIN GLIDE PATH (transformation overlay, Q2/Q3 reconciled to exit run rate)
A41: FY27 transformation delta (Year 1) | B41: 0.006 | C41: pp | D41: +60bps reconciles FY27 EBIT to ~AUD 530m (mid-upper of FY26 exit run rate AUD 495-525m per slide 28).
A42: FY28 transformation delta (Year 2 cum) | B42: 0.018 | C42: pp | D42: +180bps cumulative aligns FY28 EBIT to AUD 600m ambition.
A43: FY29 transformation delta (Year 3 cum) | B43: 0.02 | C43: pp | D43: +200bps cumulative. Final transformation tail.
A44: FY30 transformation delta (Year 4 cum) | B44: 0.02 | C44: pp | D44: Steady state.
A45: FY31 transformation delta (Year 5 cum) | B45: 0.02 | C45: pp | D45: Steady state.
...

Sheet Tax Bridge
A1: DNL Tax Rate Bridge — explicit effective glides to blended statutory in terminal
A3: JURISDICTIONAL BLENDED STATUTORY RATE
A4: Jurisdiction | B4: Revenue weight | C4: Statutory rate | D4: Contribution | E4: Source / rationale
A5: Dyno Nobel Americas (US) | B5: 0.55 | C5: 0.26 | D5: =B5*C5 -> 0.143
A6: Dyno Nobel Asia Pacific (Australia) | B6: 0.35 | C6: 0.3 | D6: =B6*C6 -> 0.105
A7: Dyno Nobel EMEA & LATAM | B7: 0.1 | C7: 0.27 | D7: =B7*C7 -> 0.027
A8: Blended statutory rate | B8: =SUM(B5:B7) -> 1 | D8: =SUM(D5:D7) -> 0.275 | E8: Used as terminal-year tax rate; per Tara's framing, structural geographic-mix advantage persists in perpetuity at ~27.5% (vs 30% AU statutory).
A10: TAX RATE GLIDE PATH (explicit period)
A11: Year | B11: Rate | E11: Glide interpolation
A12: FY27 (Y1) | B12: =Assumptions!$B$55+(D8-Assumptions!$B$55)*0/4 -> 0.225 | E12: Effective rate held in Y1.
A13: FY28 (Y2) | B13: =Assumptions!$B$55+(D8-Assumptions!$B$55)*1/4 -> 0.2375 | E13: 1/4 of the gap closed.
A14: FY29 (Y3) | B14: =Assumptions!$B$55+(D8-Assumptions!$B$55)*2/4 -> 0.25 | E14: 1/2 of the gap closed.
A15: FY30 (Y4) | B15: =Assumptions!$B$55+(D8-Assumptions!$B$55)*3/4 -> 0.2625 | E15: 3/4 of the gap closed.
A16: FY31 (Y5) + Terminal | B16: =Assumptions!$B$55+(D8-Assumptions!$B$55)*4/4 -> 0.275 | E16: Blended statutory rate reached.
A18: RATIONALE (per Tara's framing 29 May 2026)
A19: Effective rate (FY26 22.5% per management guidance) is volatile and captures everything — geographic mix, timing differences, R&D credits, JV income treatment, true-ups. Blended statutory rate (~27.5% per the jurisdictional weights above) is structural — captures only the persistent geographic-mix advantage and is what we expect in perpetuity. The 5pp gap closes over the explicit horizon as transient benefits compress (R&D, timing, JV) while the structural ~2.5pp US-mix advantage persists. All inputs above are user-overridable: change a revenue weight, a statutory rate, or the effective base rate, and the glide reflows.

Sheet P&L Summary
A1: DNL P&L — historicals + Muddle Through 5-year forecast (continuing ops, AUD m)
A3: Period | B3: FY24 | C3: FY25 | D3: H1 FY26 | E3: FY26 (base) | G3: Y1 FY27 | H3: Y2 FY28 | I3: Y3 FY29 | J3: Y4 FY30 | K3: Y5 FY31 | L3: Notes
A5: REVENUE (continuing ops)
A6: Revenue | B6: 3700 | C6: 3220 | D6: 1609.8 | E6: =Assumptions!$B$9 -> 3400 | G6: =E6*(1+Assumptions!$B$38) -> 3600.7662 | H6: =G6*(1+Assumptions!$B$38) -> 3813.3874 | I6: =H6*(1+Assumptions!$B$38) -> 4038.5636 | J6: =I6*(1+Assumptions!$B$38) -> 4277.0363 | K6: =J6*(1+Assumptions!$B$38) -> 4529.5904 | L6: Y1-Y5 compound at chain-derived 5.9%. Q1 base year reset to AUD 3,400m (continuing-ops, ex Phosphate Hill).
A8: EBIT (Group; ex IMIs) — Q2/Q3 reconciled to exit run rate
A9: EBIT margin (applied) | D9: 0.139 | E9: =Assumptions!$B$10 -> 0.141 | G9: =Assumptions!$B$10+Assumptions!$B$41+Assumptions!$B$48 -> 0.147 | H9: =Assumptions!$B$10+Assumptions!$B$42+Assumptions!$B$49 -> 0.159 | I9: =Assumptions!$B$10+Assumptions!$B$43+Assumptions!$B$50 -> 0.156 | J9: =Assumptions!$B$10+Assumptions!$B$44+Assumptions!$B$51 -> 0.151 | K9: =Assumptions!$B$10+Assumptions!$B$45+Assumptions!$B$52 -> 0.146 | L9: Base 14.1% + transformation glide (+60/+180/+200/+200/+200 bps) + gas roll-off (0/0/-50/-100/-150 bps).
A10: EBIT | D10: =D6*D9 -> 223.7622 | E10: =E6*E9 -> 479.4 | G10: =G6*G9 -> 529.31263 | H10: =H6*H9 -> 606.32859 | I10: =I6*I9 -> 630.01592 | J10: =J6*J9 -> 645.83247 | K10: =K6*K9 -> 661.3202 | L10: FY27 ~AUD 530m (within management exit run rate 495-525). FY28 ~AUD 600m (matches ambition).
A12: BELOW EBIT (per-year tax rate from Tax Bridge tab)
A13: Applied tax rate | G13: ='Tax Bridge'!$B$12 -> 0.225 | H13: ='Tax Bridge'!$B$13 -> 0.2375 | I13: ='Tax Bridge'!$B$14 -> 0.25 | J13: ='Tax Bridge'!$B$15 -> 0.2625 | K13: ='Tax Bridge'!$B$16 -> 0.275 | L13: Linear glide effective 22.5% (Y1) -> blended statutory 27.5% (Y5).
A14: Tax on EBIT | G14: =-G10*G13 -> -119.09534 | H14: =-H10*H13 -> -144.00304 | I14: =-I10*I13 -> -157.50398 | J14: =-J10*J13 -> -169.53102 | K14: =-K10*K13 -> -181.86306
A15: NOPAT (Group) | G15: =G10+G14 -> 410.21729 | H15: =H10+H14 -> 462.32555 | I15: =I10+I14 -> 472.51194 | J15: =J10+J14 -> 476.30145 | K15: =K10+K14 -> 479.45715

Sheet Balance Sheet
A1: DNL balance sheet summary at 31 March 2026 (H1 FY26 anchor; AUD m)
A3: Line | B3: AUD m | C3: Notes
A4: ASSETS (statutory presentation per Q4 review)
A5: Cash and short-term investments | B5: 647.2 | C5: Per H1 BS
A6: Trade receivables (gross) | B6: 840.5
A7: Inventory | B7: 519.1
A8: Other current assets | B8: 115.9
A9: Net PP&E | B9: 2120 | C9: Per H1 announcement page 11.
A10: Lease assets | B10: 145.1
A11: Intangible assets | B11: 2562.9 | C11: Goodwill + intangibles.
A12: Net other assets / long-term investments | B12: 433.2
A13: Net tax assets | B13: 25.3
A14: Total assets (gross per statutory) | B14: 6997.7 | C14: Per H1 statutory accounts; differs from H1 announcement net-working-capital presentation (AUD 5,863m) by ~AUD 1,135m which is gross-up of TWC items.
A16: LIABILITIES & EQUITY
A17: Trade payables (gross) | B17: 733.7
A18: Environmental & restructure liabilities | B18: 249.3 | C18: Per H1 announcement page 11. Includes AUD 82m Phosphate Hill ARO reclassified to Held for Sale; AUD 33m payments in H1.
A19: Lease liabilities | B19: 194.3 | C19: AASB 16; matches lease assets above on liability side.
A20: Net debt (reported, H1 anchor) | B20: 1260.8 | C20: Interest-bearing liabilities + capital leases - cash - hedging derivatives. Up AUD 80m H/H: buyback AUD 128m + dividends paid AUD 170m - Gibson Island proceeds AUD 198m.
A21: Net liabilities classified as held for sale | B21: 111.5 | C21: Phosphate Hill (binding sale agreement signed March 2026).
A22: Other current liabilities + other LT | B22: 248.3
A23: Total liabilities (gross) | B23: 2797.9
A24: Net assets / Total equity | B24: 4199.8 | C24: Per statutory presentation.
A26: CREDIT METRICS
A27: Net debt / EBITDA (TTM) | B27: 1.3 | C27: Per H1 disclosure. Well within 2.0x policy.
A28: Interest cover | B28: 12.5
A29: Credit rating (S&P) | B29: BBB stable
A30: Credit rating (Moody's) | B30: Baa2 stable

Sheet WACC Build
A1: DNL WACC component build-up — single discipline, Hamada with world-index beta
B3: Value | C3: Units | D3: Source / formula
A4: COST OF EQUITY (CAPM with Hamada re-levered beta)
A5: Risk-free rate (Rf) | B5: =Assumptions!$B$65 -> 0.043 | C5: % | D5: 10Y on-the-run CGS YTM, May 2026. Bloomberg GACGB10. Coupon-bearing (not zero-coupon); convention documented.
A6: Equity risk premium (ERP) | B6: =Assumptions!$B$66 -> 0.05 | C6: % | D6: Damodaran mature-Australia ERP.
A7: Beta (re-levered) | B7: =Assumptions!$B$67 -> 0.95 | D7: World-index basis (AUD-MSCI World), re-levered via Hamada with marginal tax 30% and D/E 0.197. Convention: world index for >30% non-Australian revenue companies.
A8: Cost of equity (Re = Rf + Beta x ERP) | B8: =B5+B7*B6 -> 0.0905 | C8: % | D8: CAPM.
A10: COST OF DEBT (after-tax, using marginal/statutory rate)
A11: Cost of debt, pre-tax (Rd) | B11: =Assumptions!$B$68 -> 0.06 | C11: % | D11: BBB spread ~170bps.
A12: Tax rate (consistent with Tax Bridge blended statutory) | B12: ='Tax Bridge'!$D$8 -> 0.275 | C12: % | D12: Per consistency principle: same rate used for terminal operating tax, debt tax shield, and Hamada re-levering. Linked to Tax Bridge blended statutory ~27.5%. Was 30% statutory in earlier draft; corrected for internal consistency.
A13: Cost of debt, after-tax | B13: =B11*(1-B12) -> 0.0435 | C13: % | D13: Rd x (1 - marginal tax rate).
A15: CAPITAL-STRUCTURE WEIGHTS (market value)
A16: Equity market value (E) | B16: =Assumptions!$B$69 -> 6390 | C16: AUD m | D16: Per Assumptions.
A17: Debt market value (D) | B17: =Assumptions!$B$70 -> 1260.8 | C17: AUD m | D17: Per Assumptions.
A18: Enterprise value (V = E + D) | B18: =B16+B17 -> 7650.8 | C18: AUD m
A19: E/V | B19: =B16/B18 -> 0.83520678 | C19: %
A20: D/V | B20: =B17/B18 -> 0.16479322 | C20: %
A22: APPLIED WACC (constant across scenarios; user-overridable)
A23: Baseline WACC (computed) | B23: =B19*B8+B20*B13 -> 0.082754718 | C23: % | D23: WACC = (E/V) x Re + (D/V) x Rd_at.
A24: Applied WACC | B24: =B23 -> 0.082754718 | C24: % | D24: Default: linked to baseline build. Override this cell for sensitivity (e.g., 0.0725 for -100bps test).
A26: CONVENTIONS DOCUMENTED
A27: (i) Hamada formula | D27: Beta_L = Beta_U x (1 + (1-t) x D/E), with t = blended statutory (per consistency principle; was 30% in earlier draft).
A28: (ii) Market index | D28: AUD-MSCI World for companies with >30% non-Australian revenue (DNL: 65% non-AU). ASX200 cross-check.
A29: (iii) Risk-free rate | D29: 10Y on-the-run CGS YTM (coupon-bearing). Refreshed at valuation date.
A30: (iv) Tax-rate consistency | D30: Same blended statutory rate (~27.5%, from Tax Bridge D8) used for (a) terminal operating tax, (b) debt tax shield in WACC, and (c) Hamada re-levering. Principle: internal consistency across the model.

Sheet IMI Register
A1: DNL IMI Register — H1 FY26
A3: IMI item | B3: After tax (AUD m) | C3: Gross (AUD m) | D3: P&L line | E3: Frequency context | F3: Default lean | G3: Applied
A4: Phosphate Hill impairment + site exit | B4: 125.9 | C4: 179.6 | D4: above_ebit | E4: First occurrence; tied to specific divestment. | F4: accept_as_one_off | G4: strip
A5: IPF Distribution / Gibson Island | B5: 11.2 | C5: 11.2 | D5: below_ebit | E5: Tied to FY25 divestments; final adjustments. | F5: accept_as_one_off | G5: strip
A6: Business transformation costs | B6: 3.9 | C6: 5.6 | D6: above_ebit | E6: FY24/25/26 (3 consecutive years); transformation winding down post fertilisers separation. | F6: partial_recur (borderline) | G6: strip
A7: Total IMIs (H1 FY26) | B7: =SUM(B4:B6) -> 141 | C7: =SUM(C4:C6) -> 196.4

Sheet DCF Worksheet
A1: DNL DCF v4 — Muddle Through (stub + 5-yr explicit + Gordon-growth terminal)
A3: Line | B3: Stub | C3: Y1 FY27 | D3: Y2 FY28 | E3: Y3 FY29 | F3: Y4 FY30 | G3: Y5 FY31 | H3: Terminal | I3: Notes
A5: INPUTS (from P&L + tax bridge)
A6: Revenue (AUD m) | B6: =Assumptions!$B$6*Assumptions!$B$9 -> 1193.4 | C6: ='P&L Summary'!G6 -> 3600.7662 | D6: ='P&L Summary'!H6 -> 3813.3874 | E6: ='P&L Summary'!I6 -> 4038.5636 | F6: ='P&L Summary'!J6 -> 4277.0363 | G6: ='P&L Summary'!K6 -> 4529.5904
A7: EBIT margin | B7: =Assumptions!$B$10 -> 0.141 | C7: ='P&L Summary'!G9 -> 0.147 | D7: ='P&L Summary'!H9 -> 0.159 | E7: ='P&L Summary'!I9 -> 0.156 | F7: ='P&L Summary'!J9 -> 0.151 | G7: ='P&L Summary'!K9 -> 0.146
A8: EBIT | B8: =B6*B7 -> 168.2694 | C8: =C6*C7 -> 529.31263 | D8: =D6*D7 -> 606.32859 | E8: =E6*E7 -> 630.01592 | F8: =F6*F7 -> 645.83247 | G8: =G6*G7 -> 661.3202
A9: Applied tax rate | B9: =Assumptions!$B$55 -> 0.225 | C9: ='Tax Bridge'!$B$12 -> 0.225 | D9: ='Tax Bridge'!$B$13 -> 0.2375 | E9: ='Tax Bridge'!$B$14 -> 0.25 | F9: ='Tax Bridge'!$B$15 -> 0.2625 | G9: ='Tax Bridge'!$B$16 -> 0.275
A11: FCF BRIDGE
A12: Less: tax on EBIT | B12: =-B8*B9 -> -37.860615 | C12: =-C8*C9 -> -119.09534 | D12: =-D8*D9 -> -144.00304 | E12: =-E8*E9 -> -157.50398 | F12: =-F8*F9 -> -169.53102 | G12: =-G8*G9 -> -181.86306
A13: NOPAT | B13: =B8+B12 -> 130.40878 | C13: =C8+C12 -> 410.21729 | D13: =D8+D12 -> 462.32555 | E13: =E8+E12 -> 472.51194 | F13: =F8+F12 -> 476.30145 | G13: =G8+G12 -> 479.45715
A14: Plus: D&A | B14: =B6*Assumptions!$B$13 -> 87.1182 | C14: =C6*Assumptions!$B$13 -> 262.85593 | D14: =D6*Assumptions!$B$13 -> 278.37728 | E14: =E6*Assumptions!$B$13 -> 294.81514 | F14: =F6*Assumptions!$B$13 -> 312.22365 | G14: =G6*Assumptions!$B$13 -> 330.6601
A15: Less: capex | B15: =-B6*Assumptions!$B$12 -> -95.472 | C15: =-C6*Assumptions!$B$12 -> -288.06129 | D15: =-D6*Assumptions!$B$12 -> -305.07099 | E15: =-E6*Assumptions!$B$11 -> -282.69945 | F15: =-F6*Assumptions!$B$11 -> -299.39254 | G15: =-G6*Assumptions!$B$11 -> -317.07133
A16: Less: change in WC | B16: =-Assumptions!$B$14 -> 0 | C16: =-Assumptions!$B$14 -> 0 | D16: =-Assumptions!$B$14 -> 0 | E16: =-Assumptions!$B$14 -> 0 | F16: =-Assumptions!$B$14 -> 0 | G16: =-Assumptions!$B$14 -> 0
A17: Unlevered FCFF | B17: =SUM(B13:B16) -> 122.05499 | C17: =SUM(C13:C16) -> 385.01192 | D17: =SUM(D13:D16) -> 435.63184 | E17: =SUM(E13:E16) -> 484.62763 | F17: =SUM(F13:F16) -> 489.13256 | G17: =SUM(G13:G16) -> 493.04592
A19: DISCOUNTING (mid-period, from valuation date)
A20: WACC | B20: ='WACC Build'!$B$24 -> 0.082754718 | C20: ='WACC Build'!$B$24 -> 0.082754718 | D20: ='WACC Build'!$B$24 -> 0.082754718 | E20: ='WACC Build'!$B$24 -> 0.082754718 | F20: ='WACC Build'!$B$24 -> 0.082754718 | G20: ='WACC Build'!$B$24 -> 0.082754718
A21: Time to mid-cash-flow (yrs) | B21: =Assumptions!$B$6/2 -> 0.1755 | C21: =Assumptions!$B$6+1-0.5 -> 0.851 | D21: =Assumptions!$B$6+2-0.5 -> 1.851 | E21: =Assumptions!$B$6+3-0.5 -> 2.851 | F21: =Assumptions!$B$6+4-0.5 -> 3.851 | G21: =Assumptions!$B$6+5-0.5 -> 4.851
A22: Discount factor | B22: =1/(1+B20)^B21 -> 0.98614317 | C22: =1/(1+C20)^C21 -> 0.93457659 | D22: =1/(1+D20)^D21 -> 0.86314709 | E22: =1/(1+E20)^E21 -> 0.79717694 | F22: =1/(1+F20)^F21 -> 0.73624887 | G22: =1/(1+G20)^G21 -> 0.67997752
A23: PV of FCFF | B23: =B17*B22 -> 120.36369 | C23: =C17*C22 -> 359.82313 | D23: =D17*D22 -> 376.01436 | E23: =E17*E22 -> 386.33397 | F23: =F17*F22 -> 360.1233 | G23: =G17*G22 -> 335.26014
A25: TERMINAL VALUE (Gordon growth; terminal at blended statutory tax)
A26: Terminal growth | H26: =Assumptions!$B$73 -> 0.025
A27: Terminal-year FCF (Y5 x (1+g)) | H27: =G17*(1+H26) -> 505.37207
A28: Terminal value (TFCF / (WACC-g)) | H28: =H27/(G20-H26) -> 8750.3165
A29: Time to end Y5 (yrs) | H29: =Assumptions!$B$6+Assumptions!$B$74 -> 5.351
A30: Discount factor at end Y5 | H30: =1/(1+G20)^H29 -> 0.65347581
A31: PV of terminal value | H31: =H28*H30 -> 5718.1202
A33: ENTERPRISE VALUE
A34: Sum PV explicit FCFF (stub + Y1-Y5) | H34: =SUM(B23:G23) -> 1937.9186
A35: Plus: PV terminal | H35: =H31 -> 5718.1202
A36: Enterprise value (EV) | H36: =H34+H35 -> 7656.0388
A37: Terminal share of EV (diagnostic) | H37: =H35/H36 -> 0.74687712

Sheet Equity Bridge
A1: DNL Equity Bridge v4 — full Fertilisers separation map (per slide 29) + Q6/Q8 corrections
A3: Line | B3: Component | C3: Running | D3: Notes
A5: PERIOD A WALK (anchor -> valuation date; Q6 + Q8 corrections)
A6: Net debt at 31 Mar 2026 (anchor) | B6: =Assumptions!$B$70 -> 1260.8 | D6: From Assumptions.
A7: less: operating cash flow in Period A (Q6 fix) | B7: =-Assumptions!$B$82*Assumptions!$B$81 -> -75.342466 | D7: Q6 fix: underlying OCF rate AUD 500m/yr (was AUD 290m in v3, which understated by ~AUD 30m).
A8: plus: capex paid in Period A | B8: =Assumptions!$B$83*Assumptions!$B$81 -> 38.575342
A9: (Q8: no buyback adjustment - value-neutral per methodology section 5.2)
A10: Net debt walk subtotal | B10: =SUM(B7:B8) -> -36.767123
A11: Net debt at 25 May 2026 (valuation date) | C11: =B6+B10 -> 1224.0329
A13: EQUITY-BRIDGE ADJUSTMENTS — Fertilisers separation per slide 29 (Q7)
A14: Plus: declared unpaid dividend (interim, 11 May 2026) | B14: =Assumptions!$B$86 -> 81.4 | D14: 4.6cps x 1,770m. Declared post-anchor (11 May 2026).
A15: Plus: Phosphate Hill ARO (net of provided) | B15: =Assumptions!$B$89 -> 44 | D15: Slide 29: AUD 126m at completion. AUD 82m provided (held for sale). Net AUD 44m.
A16: Plus: Phosphate Hill inventory commitment | B16: =Assumptions!$B$90 -> 80 | D16: Slide 29: ~AUD 80m inventory to Mayfair on completion.
A17: Plus: restructure execution cash cost (transformation) | B17: =Assumptions!$B$91 -> 12 | D17: Methodology section 4.4 consistency rule.
A18: Plus: Geelong remediation (NEW per Q7) | B18: =Assumptions!$B$92 -> 35 | D18: Slide 29: completion within 2 yrs of Sep 2025.
A19: Plus: Gibson Island remediation (NEW per Q7) | B19: =Assumptions!$B$93 -> 97 | D19: Slide 29: completion within ~3.5 yrs of Oct 2025.
A20: Plus: transaction costs (NEW per Q7) | B20: =Assumptions!$B$94 -> 11 | D20: Slide 29: outstanding selling/transaction/separation.
A21: Less: Perdaman contingent receivable (prob-wt) | B21: =-Assumptions!$B$97 -> -72.5 | D21: Slide 29: up to AUD 145m on milestones; 50% probability.
A22: Less: IPF Distribution deferred (prob-wt) NEW | B22: =-Assumptions!$B$100 -> -106.25 | D22: Slide 29: AUD 125m face (AUD 50m vendor note + AUD 75m Geelong deferred). 85% probability.
A23: Less: Phosphate Hill contingent (prob-wt) NEW | B23: =-Assumptions!$B$103 -> -30 | D23: Slide 29: up to AUD 100m on performance hurdles. 30% probability.
A24: Total equity-bridge adjustments | B24: =SUM(B14:B23) -> 151.65
A26: VALUE PER SHARE
A27: Enterprise value (from DCF) | C27: ='DCF Worksheet'!H36 -> 7656.0388
A28: Less: net debt at valuation date | C28: =-C11 -> -1224.0329
A29: Less: equity-bridge adjustments (net) | C29: =-B24 -> -151.65
A30: Equity value | C30: =C27+C28+C29 -> 6280.3559
A31: Divided by shares outstanding (Q8: H1 anchor, no buyback projection) | C31: =Assumptions!$B$77 -> 1770
A32: VALUE PER SHARE | C32: =C30/C31 -> 3.5482237
A34: MARKET CHECK
A35: Market reference per share | C35: =Assumptions!$B$106 -> 3.61
A36: Discount / (premium) vs market | C36: =C32/C35-1 -> -0.017112558

Sheet Sources
A1: Sources — audit trail (per Q5 review)
A3: Item | B3: Source
A4: Base year revenue / EBIT guidance | B4: H1 FY26 Investor Presentation (11 May 2026) slides 11 (outlook), 27 (segment EBIT), 28 (transformation tracker including FY26 guidance AUD 460-500m, FY28 ambition AUD 600m, exit run rate AUD 495-525m).
A5: Corporate cost treatment (Q1) | B5: H1 FY26 Investor Presentation slide 27 (Business Unit Performance — shows Corp & elim of AUD -16m within Total Explosives EBIT, confirming corporate already netted in segment numbers).
A6: H1 FY26 income statement | B6: H1 FY26 Half Year Results Announcement (11 May 2026) page 9 (Table 2 — Income Statement: Revenue AUD 1,898m; Operating margin AUD 514m; EBIT ex IMIs AUD 243m; Net debt AUD 1,261m).
A7: Balance sheet figures (Q4/Q5) | B7: H1 FY26 Half Year Results Announcement page 11 (Table 4 — net working capital presentation, total AUD 5,863m). Full statutory BS (AUD 6,997.7m gross) from the Half-Year Financial Report (published with the announcement). Difference (~AUD 1,135m) is gross-up of TWC items.
A8: Environmental & restructure liabilities (Q5) | B8: H1 FY26 Half Year Results Announcement page 11 (AUD 249.3m); composition explained on page 12 — includes Phosphate Hill ARO AUD 82m reclassified to Held for Sale, Geelong remediation accruals AUD ~33m, transformation provisions.
A9: Lease liabilities (Q5) | B9: H1 FY26 Half Year Results Announcement page 11 (AUD 194.3m); AASB 16 lease liabilities. Composition in Half-Year Financial Report notes.
A10: Operating cash flow (Q6) | B10: H1 FY26 Half Year Results Announcement page 14 (Table 8 — Cash Flow); H1 OCF AUD 145m with commentary on AUD 226m differential in TWC facility utilisation vs pcp.
A11: Buyback (Q8) | B11: H1 FY26 Half Year Results Announcement page 14 (financing cash flow); AUD 558m of AUD 900m program complete by 11 May 2026; AUD 342m remaining; buyback resumed 12 May 2026.
A12: Fertilisers separation cash flows (Q7) | B12: H1 FY26 Investor Presentation slide 29 (Fertilisers separation cash flows): IPF Distribution +AUD 125m, Perdaman +AUD 145m, Geelong remediation -AUD 35m, Gibson Island remediation -AUD 97m, Phosphate Hill ARO -AUD 126m, transaction costs -AUD 11m, Phosphate Hill contingent +AUD 100m.
A13: WACC — risk-free rate (Q9) | B13: 10-year on-the-run Commonwealth of Australia government bond yield, May 2026; Bloomberg ticker GACGB10 Index or RBA F2 series.
A14: WACC — beta (Q9) | B14: World-index basis: Damodaran industry beta data (Chemical-Specialty / Basic) cross-checked with Orica (ASX:ORI) and pre-demerger IPL observed beta. Sensitivity: ASX200 basis ~1.05-1.10.
... A16: Tax rate blended statutory (Tax discussion) | B16: Computed from jurisdictional revenue weights x statutory rates: US (55% x 26%) + Australia (35% x 30%) + EMEA/LATAM (10% x 27%) = 27.5%.
