Workbook

Sheet Cover
B1: Dyno Nobel Limited (DNL.AU) — Muddle Through valuation v4 (29 May 2026)
A3: v5 backport (17 June 2026) | B3: Scenario: | C3: Muddle Through (interior, most-likely)
A4: • Renamed Transformation Overlay → Peer-gap closure overlay (methodology §3.2 v0.6)
A5: • Beta updated to 1.10 via peer-triangulation (§3.5.3): Orica / Yara / ICL cluster midpoint; replaces v4 estimate 1.15
A6: • Cost of equity revised: Re = 9.80% (was 10.05%); WACC = 8.68% (was 8.82%)
A7: • DCF Worksheet: industry + company offset decomposition added per §11 (Step 2 → Step 3 traceability)
B8: What changed in v4 (review feedback):
B9: Q1 — Base EBIT | C9: Corrected to AUD 480m (was AUD 440m). Slide 27 + 28 confirm guidance is Total Dyno Nobel underlying, with corporate already deducted at segment level. Base margin 14.1% (was 12.9%).
B10: Q2/Q3 — Margin glide reconciled | C10: Y1 transformation delta lowered to +60bps; FY27 lands at ~AUD 530m (mid-upper exit run-rate AUD 495-525m). FY28 +180bps reaches AUD 600m ambition.
B11: Q6 — OCF run rate | C11: Period A walk-forward uses AUD 500m underlying (H1 AUD 145m grossed up for one-off TWC unwind), not AUD 290m simple-double.
B12: Q7 — Fertilisers separation cash flows | C12: Slide 29 list complete: added IPF Distribution deferred +AUD 125m (prob-weighted), Geelong remediation -AUD 35m, Gibson Island remediation -AUD 97m, transaction costs -AUD 11m, Phosphate Hill contingent +AUD 100m (prob-weighted at 30%).
B13: Q8 — Buyback inconsistency | C13: Removed Period A buyback adjustment. Per methodology section 5.2 (on-market buyback at fair value is value-neutral). Share count and net debt both at 31 March 2026 anchor.
B14: WACC (i) — Hamada | C14: Confirmed: re-lever using Hamada with marginal-rate tax shield (30%).
B15: WACC (ii) — World index | C15: Beta convention now AUD-MSCI World as primary for companies with >30% non-Australian revenue. DNL beta: 0.95 (vs 1.15 ASX200 in v3).
B16: WACC (iii) — Lower WACC | C16: Applied WACC drops 9.16% -> 8.25%. Dominant mover for the change in per-share value.
B17: Tax — Effective glides to blended statutory | C17: Effective 22.5% (Y1) -> blended statutory 27.5% (Y5/terminal), linear glide. Blended statutory = sum of jurisdictional weights x statutory rates. Captures structural US-mix advantage (persistent ~2.5pp gap to AU statutory).
B19: New tabs in v4:
B20: Tax Bridge | C20: Jurisdictional weights table + tax glide path.
B21: Sources | C21: Audit-trail tab citing specific H1 financial report pages and slides.
B23: Methodology references:
B24: Equity bridge & valuation mechanics | C24: design/methodology/equity_bridge_and_valuation_mechanics.md (sections 3.1-3.5, 4-7)
B25: Single WACC discipline | C25: section 3.5
B26: Structural headwind overlay | C26: section 3.2.1 (gas-contract roll-off remains in v4)
B27: Tax discipline (new, pending §3.6) | C27: Effective glides to blended statutory by terminal year. Sources: jurisdictional revenue mix, statutory rates by jurisdiction.
B29: Colour key:
B30: Blue text | C30: Hardcoded input — override to flow through the model
B31: Black text | C31: Formula / calculation
B32: Green text | C32: Cross-sheet link
B33: Yellow background | C33: Key assumption — flagged for attention

Sheet Assumptions
A1: Parameter | B1: Value | C1: Units | D1: Source / rationale
A2: DATES (per methodology section 7)
A3: Valuation date | B3: 25-May-2026 | D3: Today.
A4: Anchor date (financials) | B4: 31-Mar-2026 | D4: H1 FY26.
A5: Year 1 start (next FY) | B5: 1-Oct-2026 | D5: FY27 start.
A6: Stub period (years) | B6: 0.351 | C6: yrs | D6: 128 days / 365.
A8: BASE YEAR (FY26 — corrected per Q1 review)
A9: Base year revenue (FY26) | B9: 3400 | C9: AUD m | D9: FY26 continuing-ops Explosives revenue (excludes discontinued Phosphate Hill). Implied from H1 actual AUD 1,610m + H2 ~AUD 1,790m given guidance midpoint EBIT AUD 480m at margin ~14.1%.
A10: Base year EBIT margin (Group, FY26) | B10: 0.141 | C10: % | D10: AUD 480m guidance midpoint / AUD 3,400m revenue. Q1 correction: corporate ALREADY DEDUCTED in segment guidance per slides 27-28 of H1 investor presentation. Was 12.9% in v3 (-12% double-counting error).
A11: Steady-state capex/revenue (long run) | B11: 0.07 | C11: % | D11: Pre-demerger normalised pattern.
A12: FY26-27 capex/revenue (transition) | B12: 0.08 | C12: % | D12: FY26 guidance AUD 250-300m on AUD 3,400m revenue = ~8%.
A13: D&A / revenue | B13: 0.073 | C13: % | D13: Steady-state approx; FY25 actual 7.66%.
A14: Working capital change | B14: 0 | C14: AUD m / yr | D14: Smoke-test simplification: neutral.
A16: SCENARIO MACRO BASELINE (Muddle Through)
A17: DM real GDP growth | B17: 0.02 | C17: % | D17: Aus 1.8-2.2%, US 1.8-2.2%; central 2.0%.
A18: DM inflation (normalising) | B18: 0.025 | C18: % | D18: Gradually normalising; central 2.5%.
A19: Global mining real growth | B19: 0.025 | C19: % | D19: Tracks real GDP with EM mining tilt; +50bps from depletion / ore-grade decline.
A20: Gas price growth (input cost proxy) | B20: 0.02 | C20: % | D20: No commodity boom in Muddle Through; tracks long-run inflation.
A22: INDUSTRY ARCHETYPE TRANSLATION (industrial explosives)
A23: Volume formula coefficient (a) | B23: 1.15 | D23: volume_growth = a x mining_real_growth + b
A24: Volume formula constant (b) | B24: 0.004 | D24: Pickup from ore-grade decline / waste tonnage.
A25: Industry volume growth (derived) | B25: =B23*B19+B24 | C25: % | D25: a x mining_real_growth + b
A26: Pricing weight on inflation | B26: 0.7 | D26: 70% of price tracks DM inflation.
A27: Pricing weight on gas | B27: 0.3 | D27: 30% of price tracks gas input cost.
A28: Productivity sharing (bps) | B28: 0.005 | C28: % | D28: 50bps net productivity uplift per year.
A29: Industry pricing growth (derived) | B29: =B26*B18+B27*B20+B28 | C29: % | D29: pricing_weight_inflation x DM_inflation + pricing_weight_gas x gas_growth + productivity_sharing
A30: Industry nominal growth (derived) | B30: =(1+B25)*(1+B29)-1 | C30: % | D30: (1+vol) x (1+price) - 1
A32: DNL COMPANY-POSITION OFFSETS
A33: DM weighting (Aus + US) | B33: 0.9 | C33: % | D33: DNL geographic mix: ~55% US + ~35% Australia = 90% mature markets.
A34: EM weighting (DNEL: LATAM / EMEA) | B34: 0.1 | C34: % | D34: ~10% EMEA/LATAM.
A35: EM growth premium vs DM (multiplier) | B35: 1.3 | D35: EM mining-services markets growing ~30% faster than DM in nominal terms.
A36: Geographic-mix multiplier (derived) | B36: =B33+B34*B35 | D36: DM weight + EM weight x EM premium.
A37: Rivalry: competitive position vs leader | B37: -0.003 | C37: % | D37: Rivalry force (industry: MODERATE). DNL #2 vs Orica #1; scale + tech lead in electronic detonators. -30bps growth/yr at same geographic exposure. Methodology section 3.3.
A38: Rivalry: product-mix vs industry average | B38: -0.001 | C38: % | D38: Rivalry force sub-component. DNL more bulk-ANFO weighted; less electronic detonator / software exposure. -10bps growth.
A39: New entrants: DNEL pipeline uplift | B39: 0.0015 | C39: % | D39: New entrants force (industry: LOW). DNL is itself new entrant in LATAM/Africa via DNEL ramp. Time-limited 3-5 yrs. +15bps growth.
A40: Buyer / supplier / substitutes offsets | B40: 0 | C40: % | D40: Buyer power: at industry average (same mining-major customer mix). Supplier power: favourable but captured in gas roll-off overlay. Substitutes: at industry average. Net 0.
A41: DNL net company-position offset (derived) | B41: =B37+B38+B39+B40 | C41: % | D41: Net of Five-Forces-anchored offsets: -30 + -10 + 15 + 0 = -25bps.
A42: DNL nominal revenue growth (Muddle Through) | B42: =B30*B36+B41 | C42: % | D42: industry_nominal x geo_mix_multiplier + net Five-Forces offset. Per methodology section 2 + 3.3.
A44: MARGIN GLIDE PATH (transformation overlay, Q2/Q3 reconciled to exit run rate)
A45: FY27 transformation delta (Year 1) | B45: 0.006 | C45: pp | D45: +60bps reconciles FY27 EBIT to ~AUD 530m (mid-upper of FY26 exit run rate AUD 495-525m per slide 28).
...

Sheet Tax Bridge
A1: DNL Tax Rate Bridge — explicit effective glides to blended statutory in terminal
A3: JURISDICTIONAL BLENDED STATUTORY RATE
A4: Jurisdiction | B4: Revenue weight | C4: Statutory rate | D4: Contribution | E4: Source / rationale
A5: Dyno Nobel Americas (US) | B5: 0.55 | C5: 0.26 | D5: =B5*C5
A6: Dyno Nobel Asia Pacific (Australia) | B6: 0.35 | C6: 0.3 | D6: =B6*C6
A7: Dyno Nobel EMEA & LATAM | B7: 0.1 | C7: 0.27 | D7: =B7*C7
A8: Blended statutory rate | B8: =SUM(B5:B7) | D8: =SUM(D5:D7) | E8: Used as terminal-year tax rate; per Tara's framing, structural geographic-mix advantage persists in perpetuity at ~27.5% (vs 30% AU statutory).
A10: TAX RATE GLIDE PATH (explicit period)
A11: Year | B11: Rate | E11: Glide interpolation
A12: FY27 (Y1) | B12: =Assumptions!$B$59+(D8-Assumptions!$B$59)*0/4 | E12: Effective rate held in Y1.
A13: FY28 (Y2) | B13: =Assumptions!$B$59+(D8-Assumptions!$B$59)*1/4 | E13: 1/4 of the gap closed.
A14: FY29 (Y3) | B14: =Assumptions!$B$59+(D8-Assumptions!$B$59)*2/4 | E14: 1/2 of the gap closed.
A15: FY30 (Y4) | B15: =Assumptions!$B$59+(D8-Assumptions!$B$59)*3/4 | E15: 3/4 of the gap closed.
A16: FY31 (Y5) + Terminal | B16: =Assumptions!$B$59+(D8-Assumptions!$B$59)*4/4 | E16: Blended statutory rate reached.
A18: RATIONALE (per Tara's framing 29 May 2026)
A19: Effective rate (FY26 22.5% per management guidance) is volatile and captures everything — geographic mix, timing differences, R&D credits, JV income treatment, true-ups. Blended statutory rate (~27.5% per the jurisdictional weights above) is structural — captures only the persistent geographic-mix advantage and is what we expect in perpetuity. The 5pp gap closes over the explicit horizon as transient benefits compress (R&D, timing, JV) while the structural ~2.5pp US-mix advantage persists. All inputs above are user-overridable: change a revenue weight, a statutory rate, or the effective base rate, and the glide reflows.

Sheet P&L Summary
A1: DNL P&L — historicals + Muddle Through 5-year forecast (continuing ops, AUD m)
A3: Period | B3: FY24 | C3: FY25 | D3: H1 FY26 | E3: FY26 (base) | G3: Y1 FY27 | H3: Y2 FY28 | I3: Y3 FY29 | J3: Y4 FY30 | K3: Y5 FY31 | L3: Notes
A5: REVENUE (continuing ops)
A6: Revenue | B6: 3700 | C6: 3220 | D6: 1609.8 | E6: =Assumptions!$B$9 | G6: =E6*(1+Assumptions!$B$42) | H6: =G6*(1+Assumptions!$B$42) | I6: =H6*(1+Assumptions!$B$42) | J6: =I6*(1+Assumptions!$B$42) | K6: =J6*(1+Assumptions!$B$42) | L6: Y1-Y5 compound at chain-derived 5.9%. Q1 base year reset to AUD 3,400m (continuing-ops, ex Phosphate Hill).
A8: EBIT (Group; ex IMIs) — Q2/Q3 reconciled to exit run rate
A9: EBIT margin (applied) | D9: 0.139 | E9: =Assumptions!$B$10 | G9: =Assumptions!$B$10+Assumptions!$B$45+Assumptions!$B$52 | H9: =Assumptions!$B$10+Assumptions!$B$46+Assumptions!$B$53 | I9: =Assumptions!$B$10+Assumptions!$B$47+Assumptions!$B$54 | J9: =Assumptions!$B$10+Assumptions!$B$48+Assumptions!$B$55 | K9: =Assumptions!$B$10+Assumptions!$B$49+Assumptions!$B$56 | L9: Base 14.1% + transformation glide (+60/+180/+200/+200/+200 bps) + gas roll-off (0/0/-50/-100/-150 bps).
A10: EBIT | D10: =D6*D9 | E10: =E6*E9 | G10: =G6*G9 | H10: =H6*H9 | I10: =I6*I9 | J10: =J6*J9 | K10: =K6*K9 | L10: FY27 ~AUD 530m (within management exit run rate 495-525). FY28 ~AUD 600m (matches ambition).
A12: BELOW EBIT (per-year tax rate from Tax Bridge tab)
A13: Applied tax rate | G13: ='Tax Bridge'!$B$12 | H13: ='Tax Bridge'!$B$13 | I13: ='Tax Bridge'!$B$14 | J13: ='Tax Bridge'!$B$15 | K13: ='Tax Bridge'!$B$16 | L13: Linear glide effective 22.5% (Y1) -> blended statutory 27.5% (Y5).
A14: Tax on EBIT | G14: =-G10*G13 | H14: =-H10*H13 | I14: =-I10*I13 | J14: =-J10*J13 | K14: =-K10*K13
A15: NOPAT (Group) | G15: =G10+G14 | H15: =H10+H14 | I15: =I10+I14 | J15: =J10+J14 | K15: =K10+K14

Sheet Balance Sheet
A1: DNL balance sheet summary at 31 March 2026 (H1 FY26 anchor; AUD m)
A3: Line | B3: AUD m | C3: Notes
A4: ASSETS (statutory presentation per Q4 review)
A5: Cash and short-term investments | B5: 647.2 | C5: Per H1 BS
A6: Trade receivables (gross) | B6: 840.5
A7: Inventory | B7: 519.1
A8: Other current assets | B8: 115.9
A9: Net PP&E | B9: 2120 | C9: Per H1 announcement page 11.
A10: Lease assets | B10: 145.1
A11: Intangible assets | B11: 2562.9 | C11: Goodwill + intangibles.
A12: Net other assets / long-term investments | B12: 433.2
A13: Net tax assets | B13: 25.3
A14: Total assets (gross per statutory) | B14: 6997.7 | C14: Per H1 statutory accounts; differs from H1 announcement net-working-capital presentation (AUD 5,863m) by ~AUD 1,135m which is gross-up of TWC items.
A16: LIABILITIES & EQUITY
A17: Trade payables (gross) | B17: 733.7
A18: Environmental & restructure liabilities | B18: 249.3 | C18: Per H1 announcement page 11. Includes AUD 82m Phosphate Hill ARO reclassified to Held for Sale; AUD 33m payments in H1.
A19: Lease liabilities | B19: 194.3 | C19: AASB 16; matches lease assets above on liability side.
A20: Net debt (reported, H1 anchor) | B20: 1260.8 | C20: Interest-bearing liabilities + capital leases - cash - hedging derivatives. Up AUD 80m H/H: buyback AUD 128m + dividends paid AUD 170m - Gibson Island proceeds AUD 198m.
A21: Net liabilities classified as held for sale | B21: 111.5 | C21: Phosphate Hill (binding sale agreement signed March 2026).
A22: Other current liabilities + other LT | B22: 248.3
A23: Total liabilities (gross) | B23: 2797.9
A24: Net assets / Total equity | B24: 4199.8 | C24: Per statutory presentation.
A26: CREDIT METRICS
A27: Net debt / EBITDA (TTM) | B27: 1.3 | C27: Per H1 disclosure. Well within 2.0x policy.
A28: Interest cover | B28: 12.5
A29: Credit rating (S&P) | B29: BBB stable
A30: Credit rating (Moody's) | B30: Baa2 stable

Sheet WACC Build
A1: DNL WACC component build-up — single discipline, Hamada with world-index beta
B3: Value | C3: Units | D3: Source / formula
A4: COST OF EQUITY (CAPM with Hamada re-levered beta)
A5: Risk-free rate (Rf) | B5: =Assumptions!$B$69 | C5: % | D5: 10Y on-the-run CGS YTM, May 2026. Bloomberg GACGB10. Coupon-bearing (not zero-coupon); convention documented.
A6: Equity risk premium (ERP) | B6: =Assumptions!$B$70 | C6: % | D6: Damodaran mature-Australia ERP.
A7: Beta (re-levered) | B7: =Assumptions!$B$71 | D7: World-index basis (AUD-MSCI World), re-levered via Hamada with marginal tax 30% and D/E 0.197. Convention: world index for >30% non-Australian revenue companies.
A8: Cost of equity (Re = Rf + Beta x ERP) | B8: =B5+B7*B6 | C8: % | D8: CAPM.
A10: COST OF DEBT (after-tax, using marginal/statutory rate)
A11: Cost of debt, pre-tax (Rd) | B11: =Assumptions!$B$72 | C11: % | D11: BBB spread ~170bps.
A12: Tax rate (consistent with Tax Bridge blended statutory) | B12: ='Tax Bridge'!$D$8 | C12: % | D12: Per consistency principle: same rate used for terminal operating tax, debt tax shield, and Hamada re-levering. Linked to Tax Bridge blended statutory ~27.5%. Was 30% statutory in earlier draft; corrected for internal consistency.
A13: Cost of debt, after-tax | B13: =B11*(1-B12) | C13: % | D13: Rd x (1 - marginal tax rate).
A15: CAPITAL-STRUCTURE WEIGHTS (market value)
A16: Equity market value (E) | B16: =Assumptions!$B$73 | C16: AUD m | D16: Per Assumptions.
A17: Debt market value (D) | B17: =Assumptions!$B$74 | C17: AUD m | D17: Per Assumptions.
A18: Enterprise value (V = E + D) | B18: =B16+B17 | C18: AUD m
A19: E/V | B19: =B16/B18 | C19: %
A20: D/V | B20: =B17/B18 | C20: %
A22: APPLIED WACC (constant across scenarios; user-overridable)
A23: Baseline WACC (computed) | B23: =B19*B8+B20*B13 | C23: % | D23: WACC = (E/V) x Re + (D/V) x Rd_at.
A24: Applied WACC | B24: =B23 | C24: % | D24: Default: linked to baseline build. Override this cell for sensitivity (e.g., 0.0725 for -100bps test).
A26: CONVENTIONS DOCUMENTED
A27: (i) Hamada formula | D27: Beta_L = Beta_U x (1 + (1-t) x D/E), with t = blended statutory (per consistency principle; was 30% in earlier draft).
A28: (ii) Market index | D28: AUD-MSCI World for companies with >30% non-Australian revenue (DNL: 65% non-AU). ASX200 cross-check.
A29: (iii) Risk-free rate | D29: 10Y on-the-run CGS YTM (coupon-bearing). Refreshed at valuation date.
A30: (iv) Tax-rate consistency | D30: Same blended statutory rate (~27.5%, from Tax Bridge D8) used for (a) terminal operating tax, (b) debt tax shield in WACC, and (c) Hamada re-levering. Principle: internal consistency across the model.

Sheet IMI Register
A1: DNL IMI Register — H1 FY26
A3: IMI item | B3: After tax (AUD m) | C3: Gross (AUD m) | D3: P&L line | E3: Frequency context | F3: Default lean | G3: Applied
A4: Phosphate Hill impairment + site exit | B4: 125.9 | C4: 179.6 | D4: above_ebit | E4: First occurrence; tied to specific divestment. | F4: accept_as_one_off | G4: strip
A5: IPF Distribution / Gibson Island | B5: 11.2 | C5: 11.2 | D5: below_ebit | E5: Tied to FY25 divestments; final adjustments. | F5: accept_as_one_off | G5: strip
A6: Business transformation costs | B6: 3.9 | C6: 5.6 | D6: above_ebit | E6: FY24/25/26 (3 consecutive years); transformation winding down post fertilisers separation. | F6: partial_recur (borderline) | G6: strip
A7: Total IMIs (H1 FY26) | B7: =SUM(B4:B6) | C7: =SUM(C4:C6)

Sheet DCF Build-up (v5)
A1: DNL Muddle Through DCF — v5 build-up with Step 2 → Step 3 decomposition
A2: Per methodology v0.6 §11 workbook construction discipline (industry baseline + company offset shown explicitly)
A4: Line | B4: Stub | C4: Y1 FY27 | D4: Y2 FY28 | E4: Y3 FY29 | F4: Y4 FY30 | G4: Y5 FY31
A5: REVENUE GROWTH BUILD-UP (per §11 traceability requirement)
A6: Industry revenue growth p.a. (from §2.2 archetype translation) | B6: 0.0645 | C6: 0.0645 | D6: 0.0645 | E6: 0.0645 | F6: 0.0645 | G6: 0.0645
A7: Less: company-position offset (5 Forces: rivalry -30 + product mix -10 + DNEL +15) | B7: -0.0025 | C7: -0.0025 | D7: -0.0025 | E7: -0.0025 | F7: -0.0025 | G7: -0.0025
A8: =DNL revenue growth | B8: 0.062 | C8: 0.062 | D8: 0.062 | E8: 0.062 | F8: 0.062 | G8: 0.062
A9: Revenue (AUD m, computed) | B9: 1193 | C9: 3609 | D9: 3831 | E9: 4067 | F9: 4318 | G9: 4583
A11: EBIT MARGIN BUILD-UP (per §11 + §3.2 peer-gap closure framing)
A12: Base EBIT margin (FY26 normalised, per financials YAML) | B12: 0.141 | C12: 0.141 | D12: 0.141 | E12: 0.141 | F12: 0.141 | G12: 0.141
A13: Plus: peer-gap closure overlay cumulative bps (mechanism: post-demerger transformation; target Orica franchise levels) | B13: 0 | C13: 60 | D13: 180 | E13: 200 | F13: 200 | G13: 200
A14: Plus: gas-contract roll-off overlay cumulative bps (US gas contracts 2028-2030) | B14: 0 | C14: 0 | D14: 0 | E14: -50 | F14: -100 | G14: -150
A15: =EBIT margin | B15: 0.141 | C15: 0.147 | D15: 0.159 | E15: 0.156 | F15: 0.151 | G15: 0.146
A16: EBIT (AUD m, computed) | B16: 168 | C16: 531 | D16: 609 | E16: 635 | F16: 652 | G16: 669
A18: Cross-reference: detailed DCF computation continues on the 'DCF Worksheet' tab (v4 structure, unchanged).
A19: v4 used β=1.15 → WACC=8.82%. v5 uses β=1.10 (peer-triangulated per §3.5.3) → WACC≈8.68%. Per-share value impact ~+AUD 0.05.

Sheet DCF Worksheet
A1: DNL DCF v4 — Muddle Through (stub + 5-yr explicit + Gordon-growth terminal)
A3: Line | B3: Stub | C3: Y1 FY27 | D3: Y2 FY28 | E3: Y3 FY29 | F3: Y4 FY30 | G3: Y5 FY31 | H3: Terminal | I3: Notes
A5: INPUTS (from P&L + tax bridge)
A6: Revenue (AUD m) | B6: =Assumptions!$B$6*Assumptions!$B$9 | C6: ='P&L Summary'!G6 | D6: ='P&L Summary'!H6 | E6: ='P&L Summary'!I6 | F6: ='P&L Summary'!J6 | G6: ='P&L Summary'!K6
A7: EBIT margin | B7: =Assumptions!$B$10 | C7: ='P&L Summary'!G9 | D7: ='P&L Summary'!H9 | E7: ='P&L Summary'!I9 | F7: ='P&L Summary'!J9 | G7: ='P&L Summary'!K9
A8: EBIT | B8: =B6*B7 | C8: =C6*C7 | D8: =D6*D7 | E8: =E6*E7 | F8: =F6*F7 | G8: =G6*G7
A9: Applied tax rate | B9: =Assumptions!$B$59 | C9: ='Tax Bridge'!$B$12 | D9: ='Tax Bridge'!$B$13 | E9: ='Tax Bridge'!$B$14 | F9: ='Tax Bridge'!$B$15 | G9: ='Tax Bridge'!$B$16
A11: FCF BRIDGE
A12: Less: tax on EBIT | B12: =-B8*B9 | C12: =-C8*C9 | D12: =-D8*D9 | E12: =-E8*E9 | F12: =-F8*F9 | G12: =-G8*G9
A13: NOPAT | B13: =B8+B12 | C13: =C8+C12 | D13: =D8+D12 | E13: =E8+E12 | F13: =F8+F12 | G13: =G8+G12
A14: Plus: D&A | B14: =B6*Assumptions!$B$13 | C14: =C6*Assumptions!$B$13 | D14: =D6*Assumptions!$B$13 | E14: =E6*Assumptions!$B$13 | F14: =F6*Assumptions!$B$13 | G14: =G6*Assumptions!$B$13
A15: Less: capex | B15: =-B6*Assumptions!$B$12 | C15: =-C6*Assumptions!$B$12 | D15: =-D6*Assumptions!$B$12 | E15: =-E6*Assumptions!$B$11 | F15: =-F6*Assumptions!$B$11 | G15: =-G6*Assumptions!$B$11
A16: Less: change in WC | B16: =-Assumptions!$B$14 | C16: =-Assumptions!$B$14 | D16: =-Assumptions!$B$14 | E16: =-Assumptions!$B$14 | F16: =-Assumptions!$B$14 | G16: =-Assumptions!$B$14
A17: Unlevered FCFF | B17: =SUM(B13:B16) | C17: =SUM(C13:C16) | D17: =SUM(D13:D16) | E17: =SUM(E13:E16) | F17: =SUM(F13:F16) | G17: =SUM(G13:G16)
A19: DISCOUNTING (mid-period, from valuation date)
A20: WACC | B20: ='WACC Build'!$B$24 | C20: ='WACC Build'!$B$24 | D20: ='WACC Build'!$B$24 | E20: ='WACC Build'!$B$24 | F20: ='WACC Build'!$B$24 | G20: ='WACC Build'!$B$24
A21: Time to mid-cash-flow (yrs) | B21: =Assumptions!$B$6/2 | C21: =Assumptions!$B$6+1-0.5 | D21: =Assumptions!$B$6+2-0.5 | E21: =Assumptions!$B$6+3-0.5 | F21: =Assumptions!$B$6+4-0.5 | G21: =Assumptions!$B$6+5-0.5
A22: Discount factor | B22: =1/(1+B20)^B21 | C22: =1/(1+C20)^C21 | D22: =1/(1+D20)^D21 | E22: =1/(1+E20)^E21 | F22: =1/(1+F20)^F21 | G22: =1/(1+G20)^G21
A23: PV of FCFF | B23: =B17*B22 | C23: =C17*C22 | D23: =D17*D22 | E23: =E17*E22 | F23: =F17*F22 | G23: =G17*G22
A25: TERMINAL VALUE (Gordon growth; terminal at blended statutory tax)
A26: Terminal growth | H26: =Assumptions!$B$77
A27: Terminal-year FCF (Y5 x (1+g)) | H27: =G17*(1+H26)
A28: Terminal value (TFCF / (WACC-g)) | H28: =H27/(G20-H26)
A29: Time to end Y5 (yrs) | H29: =Assumptions!$B$6+Assumptions!$B$78
A30: Discount factor at end Y5 | H30: =1/(1+G20)^H29
A31: PV of terminal value | H31: =H28*H30
A33: ENTERPRISE VALUE
A34: Sum PV explicit FCFF (stub + Y1-Y5) | H34: =SUM(B23:G23)
A35: Plus: PV terminal | H35: =H31
A36: Enterprise value (EV) | H36: =H34+H35
A37: Terminal share of EV (diagnostic) | H37: =H35/H36

Sheet Equity Bridge
A1: DNL Equity Bridge v4 — full Fertilisers separation map (per slide 29) + Q6/Q8 corrections
A3: Line | B3: Component | C3: Running | D3: Notes
A5: PERIOD A WALK (anchor -> valuation date; Q6 + Q8 corrections)
A6: Net debt at 31 Mar 2026 (anchor) | B6: =Assumptions!$B$74 | D6: From Assumptions.
A7: less: operating cash flow in Period A (Q6 fix) | B7: =-Assumptions!$B$86*Assumptions!$B$85 | D7: Q6 fix: underlying OCF rate AUD 500m/yr (was AUD 290m in v3, which understated by ~AUD 30m).
A8: plus: capex paid in Period A | B8: =Assumptions!$B$87*Assumptions!$B$85
A9: (Q8: no buyback adjustment - value-neutral per methodology section 5.2)
A10: Net debt walk subtotal | B10: =SUM(B7:B8)
A11: Net debt at 25 May 2026 (valuation date) | C11: =B6+B10
A13: EQUITY-BRIDGE ADJUSTMENTS — Fertilisers separation per slide 29 (Q7)
A14: Plus: declared unpaid dividend (interim, 11 May 2026) | B14: =Assumptions!$B$90 | D14: 4.6cps x 1,770m. Declared post-anchor (11 May 2026).
A15: Plus: Phosphate Hill ARO (net of provided) | B15: =Assumptions!$B$93 | D15: Slide 29: AUD 126m at completion. AUD 82m provided (held for sale). Net AUD 44m.
A16: Plus: Phosphate Hill inventory commitment | B16: =Assumptions!$B$94 | D16: Slide 29: ~AUD 80m inventory to Mayfair on completion.
A17: Plus: restructure execution cash cost (transformation) | B17: =Assumptions!$B$95 | D17: Methodology section 4.4 consistency rule.
A18: Plus: Geelong remediation (NEW per Q7) | B18: =Assumptions!$B$96 | D18: Slide 29: completion within 2 yrs of Sep 2025.
A19: Plus: Gibson Island remediation (NEW per Q7) | B19: =Assumptions!$B$97 | D19: Slide 29: completion within ~3.5 yrs of Oct 2025.
A20: Plus: transaction costs (NEW per Q7) | B20: =Assumptions!$B$98 | D20: Slide 29: outstanding selling/transaction/separation.
A21: Less: Perdaman contingent receivable (prob-wt) | B21: =-Assumptions!$B$101 | D21: Slide 29: up to AUD 145m on milestones; 50% probability.
A22: Less: IPF Distribution deferred (prob-wt) NEW | B22: =-Assumptions!$B$104 | D22: Slide 29: AUD 125m face (AUD 50m vendor note + AUD 75m Geelong deferred). 85% probability.
A23: Less: Phosphate Hill contingent (prob-wt) NEW | B23: =-Assumptions!$B$107 | D23: Slide 29: up to AUD 100m on performance hurdles. 30% probability.
A24: Total equity-bridge adjustments | B24: =SUM(B14:B23)
A26: VALUE PER SHARE
A27: Enterprise value (from DCF) | C27: ='DCF Worksheet'!H36
A28: Less: net debt at valuation date | C28: =-C11
A29: Less: equity-bridge adjustments (net) | C29: =-B24
A30: Equity value | C30: =C27+C28+C29
A31: Divided by shares outstanding (Q8: H1 anchor, no buyback projection) | C31: =Assumptions!$B$81
A32: VALUE PER SHARE | C32: =C30/C31
A34: MARKET CHECK
A35: Market reference per share | C35: =Assumptions!$B$110
A36: Discount / (premium) vs market | C36: =C32/C35-1

Sheet Sources
A1: Sources — audit trail (per Q5 review)
A3: Item | B3: Source
A4: Base year revenue / EBIT guidance | B4: H1 FY26 Investor Presentation (11 May 2026) slides 11 (outlook), 27 (segment EBIT), 28 (transformation tracker including FY26 guidance AUD 460-500m, FY28 ambition AUD 600m, exit run rate AUD 495-525m).
A5: Corporate cost treatment (Q1) | B5: H1 FY26 Investor Presentation slide 27 (Business Unit Performance — shows Corp & elim of AUD -16m within Total Explosives EBIT, confirming corporate already netted in segment numbers).
A6: H1 FY26 income statement | B6: H1 FY26 Half Year Results Announcement (11 May 2026) page 9 (Table 2 — Income Statement: Revenue AUD 1,898m; Operating margin AUD 514m; EBIT ex IMIs AUD 243m; Net debt AUD 1,261m).
A7: Balance sheet figures (Q4/Q5) | B7: H1 FY26 Half Year Results Announcement page 11 (Table 4 — net working capital presentation, total AUD 5,863m). Full statutory BS (AUD 6,997.7m gross) from the Half-Year Financial Report (published with the announcement). Difference (~AUD 1,135m) is gross-up of TWC items.
A8: Environmental & restructure liabilities (Q5) | B8: H1 FY26 Half Year Results Announcement page 11 (AUD 249.3m); composition explained on page 12 — includes Phosphate Hill ARO AUD 82m reclassified to Held for Sale, Geelong remediation accruals AUD ~33m, transformation provisions.
A9: Lease liabilities (Q5) | B9: H1 FY26 Half Year Results Announcement page 11 (AUD 194.3m); AASB 16 lease liabilities. Composition in Half-Year Financial Report notes.
A10: Operating cash flow (Q6) | B10: H1 FY26 Half Year Results Announcement page 14 (Table 8 — Cash Flow); H1 OCF AUD 145m with commentary on AUD 226m differential in TWC facility utilisation vs pcp.
A11: Buyback (Q8) | B11: H1 FY26 Half Year Results Announcement page 14 (financing cash flow); AUD 558m of AUD 900m program complete by 11 May 2026; AUD 342m remaining; buyback resumed 12 May 2026.
A12: Fertilisers separation cash flows (Q7) | B12: H1 FY26 Investor Presentation slide 29 (Fertilisers separation cash flows): IPF Distribution +AUD 125m, Perdaman +AUD 145m, Geelong remediation -AUD 35m, Gibson Island remediation -AUD 97m, Phosphate Hill ARO -AUD 126m, transaction costs -AUD 11m, Phosphate Hill contingent +AUD 100m.
A13: WACC — risk-free rate (Q9) | B13: 10-year on-the-run Commonwealth of Australia government bond yield, May 2026; Bloomberg ticker GACGB10 Index or RBA F2 series.
A14: WACC — beta (Q9) | B14: World-index basis: Damodaran industry beta data (Chemical-Specialty / Basic) cross-checked with Orica (ASX:ORI) and pre-demerger IPL observed beta. Sensitivity: ASX200 basis ~1.05-1.10.
... A16: Tax rate blended statutory (Tax discussion) | B16: Computed from jurisdictional revenue weights x statutory rates: US (55% x 26%) + Australia (35% x 30%) + EMEA/LATAM (10% x 27%) = 27.5%.
